Workbook

Sheet 00_表紙
B2: JMeter負荷試験「どこから負荷をかけるか」方式比較ガイド
B3: Cognito M2M認証 × プライベートAPI Gateway（PrivateLink／NLB） × VPCリンク v2 × 内部ALB × ECS × RDS Proxy × Aurora Serverless v2（MySQL）
B6: このガイドについて
B7: 作成日 | C7: 2026年10月18日
B8: 情報の基準 | C8: 2026年10月18日時点で確認した AWS 公式ドキュメント・発表と Apache JMeter の公式情報（出典は「17_参考資料」）
B9: このガイドの目的 | C9: JMeterで対象APIを負荷試験するとき、①Cognitoのトークン取得から全経路を通す（方式A）、②VPCエンドポイントサービス（NLB）から入れる（方式B）、③内部ALBに直接入れる（方式C）のどれを使うべきかを、テストのしやすさ・本番の再現性・安全性・費用の観点で厳密に評価します。あわせて、方式ごとに「JMeter用に変更・追加・確認すべき設定」をもれなく示します。
B10: 読んでほしい人 | C10: 試験を計画・実施する人、インフラ／ネットワーク担当、アプリ担当、判断する立場の人。専門用語が苦手な人のために、「02_やさしい説明」（小学生にもわかるたとえ話）と「16_用語集」を用意しています。
B11: 想定している経路（API） | C11: JMeter → 利用側インターフェイスVPCエンドポイント（PrivateLink） → VPCエンドポイントサービス（NLB） → execute-api インターフェイスVPCエンドポイント → API Gateway（プライベートREST API＋Cognitoオーソライザー） → VPCリンク v2 → 内部ALB → ECSサービス（タスク内コンテナ） → RDS Proxy → Aurora Serverless v2（MySQL）
B12: 想定している経路（トークン） | C12: JMeter →（NATゲートウェイ等の外向き通信）→ Cognito のトークンエンドポイント（/oauth2/token）または GetClientToken API
B14: 前提（このガイドの想定）
B15: 前提1 | C15: 本番のM2Mクライアントは、Cognitoのクライアントクレデンシャル（client_credentials）でアクセストークンを取得し、有効期限まで使い回す（AWSの推奨どおり）。
B16: 前提2 | C16: API Gateway はプライベート REST API。各メソッドに Cognito ユーザープールオーソライザーと OAuth スコープを設定している。
B17: 前提3 | C17: NLB は VPC エンドポイントサービス（PrivateLink）として公開され、ターゲットは execute-api インターフェイスVPCエンドポイントの IP アドレス。利用者は自分の VPC に作ったインターフェイスVPCエンドポイントから接続する。
B18: 前提4 | C18: API Gateway は VPCリンク v2 で内部 ALB へプライベート統合している（REST API では2025年11月から可能になった構成）。
B19: 前提5 | C19: 試験は本番と分けた、本番と同じ作りの環境（できれば別の AWS アカウント）で行う。
B20: 前提6 | C20: 実際の構成がこの想定と違う場合（例：NLB で TLS を終端している、カスタムドメインを使っている）は、該当する確認項目を自分の環境に読み替えてください。
B22: 結論（ひとことで）
B23: 結論 | C23: 合否判定は「方式A（フル経路）」、その前のボトルネック調査は「方式C（ALB直結）」。トークン取得はJMeterのシナリオに含めるが、毎リクエストではなく「最初に1回＋期限前に更新」。JMeter専用のCognitoオーソライザーは不要（専用アプリクライアントを1つ追加するだけ）。
B25: 読み方
B26: 急いでいる人 | C26: 01_結論 → 06_評価マトリクス → 10_設定変更一覧 の順に読む
B27: はじめての人・説明する相手がいる人 | C27: 02_やさしい説明 → 03_歴史と背景 → 04_構成と経路
B28: 実際に作業する人 | C28: 10_設定変更一覧 → 11_JMeter設計 → 12_負荷とトークン試算 → 15_実施手順
B29: 結果を判断する人 | C29: 13_監視と判定 → 14_誤解と落とし穴
B31: 凡例
B32: ◎ | C32: 最適／必須（必ず実施・確認する）
B33: ○ | C33: 適している／推奨
B34: △ | C34: 条件付き（該当する場合だけ実施）／注意が必要
B35: × | C35: 適さない／使えない
B36: － | C36: 不要／関係しない
B37: ■ | C37: その方式で通る部品（「■（入口）」はJMeterが最初につなぐ場所）
B38: ● | C38: トークン取得のときだけ通る（最初と更新のとき）
B39: □ | C39: その方式では通らない部品
B40: （入力欄の例） | C40: 薄い灰色で塗ったセルは入力欄です。値を変えると数式で自動計算されます（06・12・13シート）
B42: シート一覧（シート名をクリックすると移動します）
B43: 00_表紙 | C43: このガイドの目的・前提・凡例・シート一覧
B44: 01_結論 | C44: 結論、ご質問の論点への回答、判断フロー、進め方、やってはいけないこと
B45: 02_やさしい説明 | C45: 小学生にもわかる「遊園地」のたとえ話で、全体と3つの方式を説明
B46: 03_歴史と背景 | C46: 各技術が登場した歴史と背景、この問いが必要になった経緯
B47: 04_構成と経路 | C47: 経路上の部品ごとの役割・制限・監視点と、各方式が通る範囲
B48: 05_方式比較 | C48: 3方式のメリット・デメリットを観点ごとに比較
...

Sheet 01_結論
B2: 結論（エグゼクティブサマリー）
B3: 3方式の使い分け、ご質問の論点への回答、判断フロー、進め方、やってはいけないこと
B6: 1. 結論
B7: No | C7: 結論 | D7: 理由・内容 | E7: 関連シート
B8: 1 | C8: 1つに決めず、目的で使い分ける | D8: 合否判定（利用者が体験する性能の保証）は方式A、ボトルネック調査・チューニングは方式C、方式Bは補助（PrivateLink区間の切り分けや、利用側の環境をすぐ用意できないときの代替）。目的が違えば、最適な入口も変わります（06_評価マトリクスで、目的別に重みを変えて確認しています）。 | E8: 06_評価マトリクス
B9: 2 | C9: 合否判定は方式A（フル経路）で行う | D9: API Gateway のスロットリングや29秒の統合タイムアウト、Cognitoオーソライザーによる認可、PrivateLink・NLB まで含めて、利用者と同じ条件で測れるのは方式Aだけです。区間ごとの内訳は CloudWatch のメトリクスとログで分解できます（13_監視と判定）。 | E9: 04_構成と経路、13_監視と判定
B10: 3 | C10: トークン取得は「シナリオに含める」が「毎リクエストは取らない」 | D10: setUpスレッドグループで最初に1回取得 → 全スレッドで共有 → 期限の5分前に取り直す、が正解です。理由は3つ。①本番のM2Mクライアントもトークンを使い回すのが作法（AWS公式も推奨）。②トークン発行（ClientAuthentication）は1アカウント・1リージョンあたり150RPSが上限で、他システムと共有・引き上げ不可。③M2Mトークンは1件ごとに課金（米国東部の例：1件0.00225USD、無料枠なし）。毎リクエスト取得にすると、APIではなくCognitoを試験することになります。 | E10: 11_JMeter設計、12_負荷とトークン試算
B11: 4 | C11: 「パブリックに公開された端末」は不要 | D11: 必要なのは、①Cognitoのトークンエンドポイントへの「外向き」HTTPS通信（NATゲートウェイやプロキシ経由で可）と、②プライベートな入口（利用側VPCエンドポイント／NLB／ALB）への到達性だけです。JMeterはVPC内のプライベートサブネットに置けます。外向き通信を許可できない場合は、JMeterの外でトークンを取って渡すか、2026年8月に追加された GetClientToken API を cognito-idp のVPCエンドポイント経由で呼びます（ユーザープールにドメインが無い場合に限る）。 | E11: 10_設定変更一覧（2-5、2-6）
B12: 5 | C12: JMeter専用のCognitoオーソライザーは追加しない | D12: 同じユーザープールに「JMeter専用アプリクライアント」を1つ作り、本番クライアントと同じスコープを許可すれば、既存のオーソライザーがそのまま検証します。オーソライザーの追加・付け替えは本番と同じAPI定義を書き換えることになり、試験対象そのものが変わります（消し忘れはセキュリティ事故にもつながります）。 | E12: 10_設定変更一覧（1-1、4-1、4-2）
B13: 6 | C13: 方式C（ALB直結）は「裏口」なので、期限付き・最小限で | D13: ALBのセキュリティグループに「JMeterのセキュリティグループだけ」を期限付きで許可し、終わったら必ず削除して、届かないことを確認します。API Gateway が付ける Host・パス（ステージ名）・ヘッダーを再現しないと、本番と違う処理になります。結果は前段を含まない「バックエンドの実力」として扱い、合否判定には使いません。 | E13: 09_方式C_ALB直結、10_設定変更一覧（5-1〜5-5）
B14: 7 | C14: 方式Bは「Cognitoを避ける方法」にはならない | D14: 認可は API Gateway で行うため、NLBから入ってもトークンは必要です。NLBに直結するときは、本番と同じFQDN（SNIとHost）のままNLBへ向ける工夫（JMeterのDNS Cache Managerの静的ホスト）が必要で、手間は方式Aとあまり変わりません。 | E14: 08_方式B_NLB入口、10_設定変更一覧（3-5〜3-7）
B16: 2. 評価結果（06_評価マトリクスの数式を参照。重みや点数を変えると自動で更新されます）
B17: No | C17: 方式 | D17: いちばん向いている使い方／おすすめ度 | E17: 総合点（100点満点）と順位
B18: 1 | C18: 方式A（フル経路） | D18: 受入判定（合否）、SLA確認、耐久試験、スパイク試験 ◎ 受入判定の主軸 | E18: ="受入判定 "&TEXT('06_評価マトリクス'!G21,"0.0")&" 点（"&'06_評価マトリクス'!G22&" 位・"&'06_評価マトリクス'!G23&"）"&CHAR(10)&"ボトルネック調査 "&TEXT('06_評価マトリクス'!G24,"0.0")&" 点（"&'06_評価マトリクス'!G25&" 位）" -> 受入判定 73.0 点（1 位・適格） ボトルネック調査 56.0 点（3 位）
B19: 2 | C19: 方式B（NLB入口） | D19: PrivateLink区間の切り分け、利用側の環境を用意できないときの代替 ○〜△ 補助（必要なときだけ） | E19: ="受入判定 "&TEXT('06_評価マトリクス'!H21,"0.0")&" 点（"&'06_評価マトリクス'!H22&" 位・"&'06_評価マトリクス'!H23&"）"&CHAR(10)&"ボトルネック調査 "&TEXT('06_評価マトリクス'!H24,"0.0")&" 点（"&'06_評価マトリクス'!H25&" 位）" -> 受入判定 67.0 点（2 位・適格） ボトルネック調査 61.0 点（2 位）
B20: 3 | C20: 方式C（ALB直結） | D20: ボトルネック調査、チューニング、バックエンドの限界性能の把握 ◎ 事前調査の主軸／× 受入判定には使えない | E20: ="受入判定 "&TEXT('06_評価マトリクス'!I21,"0.0")&" 点（"&'06_評価マトリクス'!I22&" 位・"&'06_評価マトリクス'!I23&"）"&CHAR(10)&"ボトルネック調査 "&TEXT('06_評価マトリクス'!I24,"0.0")&" 点（"&'06_評価マトリクス'!I25&" 位）" -> 受入判定 59.0 点（3 位・不適格） ボトルネック調査 79.0 点（1 位）
B22: 3. ご質問の論点への回答（テストのしやすさ）
B23: No | C23: 論点 | D23: 回答 | E23: 関連シート
B24: 1 | C24: Cognitoでトークンを取得してAPI Gatewayを呼ぶには、パブリックにアクセス可能な端末が必要？ | D24: 外向きのHTTPS通信ができれば足り、外から受信できる公開端末は不要です。プライベートサブネット＋NATゲートウェイで実行できます。ただし、トークンエンドポイント（ユーザープールのドメイン）はPrivateLink非対応なので、外向きの経路は必要です（例外：ドメインの無いユーザープールで GetClientToken を cognito-idp のVPCエンドポイント経由で呼ぶ場合）。 | E24: 10_設定変更一覧（2-5、2-6）
B25: 2 | C25: 内部ALBならCognitoは不要だが、ALBの許可設定が必要？ | D25: そのとおりです。ALBのセキュリティグループに、JMeterのセキュリティグループからのインバウンドを期限付きで追加します。加えて、API Gateway が付ける Host・パス・ヘッダーの再現が必要です。ALBでJWT検証（2025年11月〜）を有効にしている場合や、アプリ自身がJWTを検証している場合は、方式Cでもトークンが必要です。 | E25: 09_方式C_ALB直結、10_設定変更一覧（5-1〜5-5）
B26: 3 | C26: Cognitoの設定をJMeter用に追加する必要は？ | D26: 方式A・Bでは必要です。既存のユーザープールに、JMeter専用アプリクライアント（クライアントシークレットあり、client_credentials を許可、本番と同じスコープ）を追加し、試験後に削除します。リソースサーバーやスコープの新規追加は不要です（新しいスコープを作ると、メソッド側の設定変更が必要になるため）。 | E26: 10_設定変更一覧（1-1〜1-9）
B27: 4 | C27: API GatewayのCognitoオーソライザーをJMeter専用に追加する必要は？ | D27: 不要（非推奨）です。既存のオーソライザーは、同じユーザープールのどのアプリクライアントのトークンでも検証します。確認すべきなのは、メソッドにOAuthスコープが設定されていること（未設定だとアクセストークンが401になる）と、トークン検証の正規表現（aud）が設定されていないこと（アクセストークンには aud が無いため拒否される）です。 | E27: 10_設定変更一覧（4-1、4-2）
B28: 5 | C28: VPCエンドポイントサービス（NLB）につなげるのは良い方法？ | D28: Cognitoは結局必要で、PrivateLinkの利用側区間を通らないぶん本番との差が出ます。利用側の環境を用意できるなら方式A、PrivateLink区間の影響を切り分けたいときの補助として方式Bを使います。なお、JMeter専用のVPCにエンドポイントサービス宛てのインターフェイスエンドポイントを作って接続するやり方は、経路上は方式Aと同じなので、本ガイドでは方式Aとして扱います。 | E28: 08_方式B_NLB入口、05_方式比較
B30: 4. 判断フロー（上から順に答える）
B31: No | C31: 質問 | D31: 「はい」のとき | E31: 関連シート
B32: 1 | C32: Q1 目的は「本番で大丈夫か」の合否判定？ | D32: はい → 方式A（事前に方式Cでチューニングしておくと手戻りが減る） | E32: 07_方式A_フル経路
B33: 2 | C33: Q2 目的はバックエンド（ECS・RDS Proxy・Aurora）の限界やボトルネックの特定？ | D33: はい → 方式C | E33: 09_方式C_ALB直結
B34: 3 | C34: Q3 利用側の環境（利用側VPC）を用意できない／PrivateLink区間の影響を切り分けたい？ | D34: はい → 方式B（または JMeter専用の利用側VPCを作って方式A） | E34: 08_方式B_NLB入口
B35: 4 | C35: Q4 JMeterからCognitoへ外向き通信ができない？ | D35: はい → ①JMeterの外でトークンを取得して渡す ②GetClientToken＋cognito-idp のVPCエンドポイント（ドメインの無いユーザープールのみ） ③NAT／プロキシを試験期間だけ許可 | E35: 10_設定変更一覧（2-6）
B36: 5 | C36: Q5 目標RPSが API Gateway のアカウント上限（10,000RPS）を超える？ | D36: はい → Service Quotas で事前に引き上げを申請（承認に時間がかかることがある） | E36: 10_設定変更一覧（0-7）
B37: 6 | C37: Q6 試験時間がトークンの有効期限（既定60分）より長い？ | D37: はい → 更新用のスレッドグループを入れる（11_JMeter設計） | E37: 11_JMeter設計
B38: 7 | C38: Q7 5分以内に負荷が2倍を超えて跳ね上がるスパイク試験をする？ | D38: はい → ALB／NLB の LCU予約を検討（本番でも予約するかどうかとそろえる） | E38: 10_設定変更一覧（0-8）
B40: 5. おすすめの進め方
B41: No | C41: フェーズ | D41: 内容 | E41: 関連シート
B42: 1 | C42: フェーズ0 計画 | D42: 目的・合否基準・負荷の形（RPS）を数値で決め、関係者の承認を得る | E42: 06・12・13
B43: 2 | C43: フェーズ1 準備 | D43: JMeterをVPC内に用意し、Cognitoの専用アプリクライアント、ネットワーク・名前解決・監視を設定する | E43: 10・11
B44: 3 | C44: フェーズ2 疎通 | D44: 1スレッド・1リクエストで、方式Aと方式Cの両方が200になることを確認する | E44: 11
B45: 4 | C45: フェーズ3 方式Cでベースライン | D45: バックエンドだけの実力を測り、最初に詰まる部品を見つけて直す | E45: 09・13
B46: 5 | C46: フェーズ4 方式Aで本番相当 | D46: ピーク負荷・スパイク・耐久（トークン更新を含む）を測って合否を判定し、方式Cとの差から前段のオーバーヘッドをつかむ | E46: 07・13
B47: 6 | C47: フェーズ5 方式B（必要なとき） | D47: PrivateLink利用側区間の影響を切り分ける | E47: 08
...

Sheet 02_やさしい説明
B2: やさしい説明（小学生にもわかる「遊園地」のたとえ）
B3: むずかしい言葉は「16_用語集」にもまとめています
B6: はじめに
B7: このしくみを「遊園地」にたとえてみます。JMeterは、本番の日の前に「お客さん役」をたくさん作って、遊園地がとても混んでもちゃんと動くかを確かめるロボットです。どこからロボットを入れるかで、わかることが変わります。
B9: 1. 部品を遊園地にたとえると
B10: 部品 | C10: たとえ（遊園地） | D10: ほんとうの役割 | E10: ここがポイント
B11: JMeter | C11: お客さん役のロボット軍団 | D11: たくさんのリクエストを同時に送り、応答の速さやエラーを測る道具（Apache JMeter） | E11: 本番の日の前に「混んでもこわれないか」を確かめるリハーサル係
B12: Cognito（トークン発行） | C12: チケット売り場 | D12: M2M（機械どうし）用のアクセストークン（JWT）を発行する認証サービス（Amazon Cognito） | E12: チケット売り場は1秒に150枚までしか配れず、1枚ごとにお金がかかる
B13: アクセストークン | C13: 手首につけるリストバンド | D13: 「だれが・どこまで使ってよいか（スコープ）」が書かれ、署名された証明書。ふつうは60分有効 | E13: 1回もらえば期限まで何度でも使える。毎回もらいに行かない
B14: クライアントID／シークレット | C14: ロボットの会員番号と合言葉 | D14: トークンをもらうための身分証明（アプリクライアントの識別子と、秘密の文字列） | E14: 合言葉はひみつ。紙（JMXファイル）に書いてみんなに配らない
B15: 利用側インターフェイスVPCエンドポイント（PrivateLink） | C15: となり町から続く専用地下トンネルの入口 | D15: インターネットを通らずに、別のVPC・別のアカウントのサービスへつなぐ入口 | E15: 外の道路を通らないので安全。本物のお客さんはここから来る
B16: VPCエンドポイントサービス（NLB） | C16: トンネル出口の交通整理係 | D16: PrivateLinkでサービスを公開するための仕組みと、その本体のネットワークロードバランサー（L4で高速に振り分け） | E16: 荷物の中身は見ずに、とにかく速く道を振り分ける
B17: execute-api VPCエンドポイント | C17: 受付の建物に入るドア | D17: プライベートAPIに入るための専用の入口（API Gateway用のインターフェイスVPCエンドポイント） | E17: このドアからしか受付に入れない
B18: API Gateway（プライベートREST API） | C18: 正門の受付・改札 | D18: 認可（トークンの確認）、流量制限（スロットリング）、変換、振り分けを行うAPIの玄関 | E18: 混みすぎたら入場制限（429）。30秒近く待たせると打ち切り（504）
B19: Cognitoオーソライザー | C19: 改札のリストバンド読み取り機 | D19: トークンの署名・有効期限・スコープを確認する API Gateway の機能 | E19: 読み取り機は1台で十分。ロボット専用の読み取り機は作らなくてよい
B20: VPCリンク v2 | C20: 受付から奥のエリアへの関係者通路 | D20: API Gateway から VPC の中の内部ALBへ、プライベートにつなぐ通路 | E20: 2025年11月から、REST APIでもNLBをはさまずにALBへ直接つながるようになった
B21: 内部ALB | C21: エリアの案内係 | D21: HTTPの中身（パスやHost）を見て、どのコンテナへ送るかを決めるロードバランサー（L7） | E21: 宛名（Host・パス）がちがうと、ちがうお店に案内してしまう
... B24: Aurora Serverless v2（MySQL） | C24: 大きさが自動で変わる魔法の倉庫 | D24: 負荷に合わせて容量（ACU）を自動で増やしたり減らしたりするデータベース | E24: 大きくなるには少し時間がかかる。準備運動（ウォームアップ）が大事
B26: 2. 3つの方式を遊園地にたとえると
B27: 方式 | C27: どう進む？ | D27: いいところ | E27: 気をつけるところ
B28: 方式A 正門から入る（フル経路） | C28: ロボットがチケット売り場でリストバンドをもらい（1時間に1回だけ）、本物のお客さんと同じトンネル → 正門の改札 → 案内係 → お店 → 倉庫と進む | D28: いちばん本番に近い練習。「本番で大丈夫？」の合格テストができる | E28: チケット売り場は「外の大通り」沿いにあるので、そこへ出る道（NATゲートウェイ）が必要。でも、外から入ってこられる入口（公開された端末）はいらない
B29: 方式B トンネルの出口から入る（NLB入口） | C29: トンネルの出口にいる交通整理係のところから入り、そこから先は本物と同じように進む | D29: 正門から奥（改札・お店・倉庫）は本物と同じように試せる | E29: 正門の改札はあるので、結局リストバンドは必要。トンネルの中の練習にはならない
B30: 方式C 裏口から入る（ALB直結） | C30: 正門を通らず、裏口から案内係のところへ直接行く | D30: リストバンドがいらず、お店と倉庫の実力をじっくり測れる。弱いところを見つけやすい | E30: 裏口のカギを開ける（ALBのセキュリティグループで許可する）必要がある。終わったらすぐカギを閉める。正門の混み具合やチェックの時間は測れない
B32: 3. まとめ（ここだけ覚えればOK）
B33: ひとこと | C33: 説明
B34: 合格テストは正門から | C34: 「本番の日に大丈夫か」は、本物のお客さんと同じ道（方式A）で確かめます。
B35: 弱いところ探しは裏口から | C35: 「お店や倉庫のどこが先に苦しくなるか」を調べるのは、裏口（方式C）が便利です。
B36: トンネルの調査は出口から | C36: 「トンネルのせいで遅いの？」を調べたいときだけ、トンネルの出口（方式B）から入ります。
B37: リストバンドは毎回もらわない | C37: チケット売り場は1秒に150枚までしか配れず、1枚ごとにお金がかかります。最初に1回もらって、切れる5分前に付け替えれば十分です。
B38: 外への出口は必要、入口はいらない | C38: チケット売り場は外の大通りにあるので、外へ出る道（NAT）は必要です。でも、外の人が入ってこられる入口（公開された端末）はいりません。
B39: ロボット専用の読み取り機はいらない | C39: 改札の読み取り機は、同じチケット売り場のリストバンドならどれでも読めます。ロボット用の会員証（アプリクライアント）を1つ作るだけで大丈夫です。
B40: 裏口のカギは必ず閉める | C40: 裏口（ALB）を開けたら、テストが終わったらすぐに閉めて、閉まっていることを確かめます。
B41: 新しいチケット自販機（2026年8月〜） | C41: トンネルの中でも使えるチケット自販機（GetClientToken）ができました。ただし、外の大通りのチケット売り場（ドメイン）を閉めた遊園地だけが、トンネルの中で使えます。

Sheet 03_歴史と背景
B2: 歴史と背景（登場の歴史・背景・必要になった経緯）
B3: 年表の年は発表・一般提供の時期の目安です
B6: 1. 年表：どの技術が、なぜ生まれたか
B7: 年 | C7: 出来事 | D7: 背景（なぜ生まれた・必要になった） | E7: 今回の試験への影響
B8: 1990年代 | C8: Webの普及と、商用の負荷試験ツールの登場 | D8: インターネットで多くの人が同時にサービスを使うようになり、「混んでも壊れないか」を本番前に確かめる必要が生まれた | E8: 「負荷試験」という工程の始まり
B9: 1998年 | C9: Apache JMeter 誕生（Stefano Mazzocchi が Apache JServ〔のちの Tomcat〕の性能試験のために作成） | D9: 無料で使え、自由に改造できる負荷試験ツールが求められた | E9: 今も代表的なOSS。2026年10月時点の公式最新版は 5.6.3（Java 8以上で動作、Java 17以上を推奨）
B10: 2006年 | C10: AWS の S3・EC2 が始まる | D10: サーバーを必要なときに必要な分だけ借りられるクラウドの時代へ | E10: 負荷をかける側のマシン（JMeterの実行機）も、必要な台数だけ用意できるようになった
B11: 2007〜2012年 | C11: OAuth 1.0（2007年）→ OAuth 2.0（RFC 6749・RFC 6750、2012年） | D11: パスワードを渡さずに「使ってよい範囲」だけを渡す仕組みが必要になった。機械どうしの通信のためにクライアントクレデンシャル方式が定義された | E11: 今回のM2Mトークン取得（client_credentials）の原典
B12: 2009年 | C12: Amazon VPC 登場 | D12: クラウドの中に、自社専用の閉じたネットワークを作りたいという企業のニーズ | E12: 「VPCの中からしか届かないAPI」が生まれる土台。JMeterもVPCの中に置く必要がある理由
B13: 2014年 | C13: Amazon Cognito 登場 | D13: モバイル・Webアプリの認証を自前で作らずに済ませたいニーズ | E13: トークンを発行するサービスとしての Cognito の始まり
B14: 2015年 | C14: Amazon API Gateway（7月）、Amazon ECS の一般提供、JWT の標準化（RFC 7519） | D14: APIの玄関（認証・流量制御・監視）をサーバー管理なしで提供したい。コンテナを大規模に動かしたい。トークンの中身を署名付きで持ち運びたい | E14: API Gateway のスロットリング（既定10,000RPS）が試験の上限になりうる。JWTなので、Cognitoに毎回問い合わせずに検証できる
B15: 2016年 | C15: Cognito ユーザープール、API Gateway の Cognito オーソライザー、ALB が登場 | D15: 利用者・アプリの認証基盤をマネージドにしたい。HTTPの中身を見て振り分けたい | E15: オーソライザーでJWTを検証する、今回の構成の土台
B16: 2017年 | C16: NLB（9月）、AWS PrivateLink のエンドポイントサービス・API Gateway の VPCリンク（NLB経由）・AWS Fargate（11月）。このころ Cognito の OAuth 2.0 機能（リソースサーバー・カスタムスコープ等）も整う | D16: VPCどうし・アカウントどうしを、インターネットを通さずに一方向で安全につなぎたい（IPアドレスが重なっていてもよい）。PrivateLinkで公開するにはNLBが必要 | E16: 構成にある「VPCエンドポイントサービス（NLB）」の起源
B17: 2018年 | C17: API Gateway のプライベートAPI（VPCエンドポイント経由でのみ呼べるAPI） | D17: 社内・システム間のAPIをインターネットに出したくない（金融・公共などの要件） | E17: インターネット上の負荷試験サービスからは届かない。JMeterをVPCの中（またはつながったネットワーク）に置く必要が生まれた
B18: 2020年 | C18: RDS Proxy の一般提供（6月）、HTTP API の一般提供（VPCリンク v2：ALB／NLB／Cloud Map） | D18: サーバーレスやコンテナからの大量のDB接続を整理したい。より安く簡単なAPIがほしい | E18: RDS Proxy の接続数・待ち時間・ピン留めが試験の観察点に。VPCリンク v2 の始まり
... B23: 2026年 | C23: Cognito の GetClientToken API（8月31日）：ドメインなしで M2M トークンを取得でき、AWS WAF と PrivateLink に対応。JMeter の次期メジャー版は Java 17 以上が必要になる予定 | D23: ホストUI用のドメインを持たずにM2Mを実現したい。インターネットへ出ずにトークンを取りたい | E23: ユーザープールにドメインが無ければ、インターネットへの出口なしでJMeterがトークンを取れる道ができた（ドメインを使う今の構成では、そのままでは使えない）
B25: 2. 「どこから負荷をかけるか」が問題になった経緯
B26: 段階 | C26: 何が起きたか | D26: その結果 | E26: 今回の試験では
B27: ① 入口がひとつだった時代 | C27: Webサーバー1台＋DBのような単純な構成で、入口から負荷をかければ全体を測れた | D27: どこから負荷をかけるかで迷う必要がほとんどなかった | E27: －
B28: ② 部品が直列に増えた | C28: クラウドとマネージドサービスで、入口から奥まで多くの部品（認証、APIの玄関、ロードバランサー、コンテナ、接続プール、DB）がつながるようになった | D28: どこで詰まっているかが見えにくくなり、「途中から負荷をかけて切り分ける」需要が生まれた | E28: 方式C（ALB直結）が「切り分け用」として意味を持つ
B29: ③ APIが閉域になった | C29: セキュリティ要件で、APIをインターネットに出さないプライベートAPI＋PrivateLinkが広まった | D29: インターネット上の負荷試験サービスからは届かず、負荷をかける側もVPCの中に置く必要が出た | E29: JMeterの置き場所が、方式選びの大きな条件になった
B30: ④ 認証がトークンになった | C30: OAuth 2.0 と JWT が標準になり、機械どうしの通信もトークンで認可するようになった | D30: 負荷試験ツールもトークンを取得・管理する必要が出た。トークンを発行する側（Cognito）にも速度の上限がある | E30: 「トークン取得をシナリオに含めるか」という論点が生まれた
B31: ⑤ トークン取得にお金がかかるようになった | C31: 2024年5月から Cognito の M2M トークンは件数で課金（2025年11月にアプリクライアントの料金は廃止、トークンの料金は継続） | D31: 「毎回トークンを取る」作りは、上限だけでなく費用の面でも不利になった | E31: トークンは使い回す（キャッシュする）のが前提に
B32: ⑥ 経路がシンプルに、閉域が広がった | C32: 2025〜2026年に、VPCリンク v2 による ALB 直結、Cognito の PrivateLink 対応、GetClientToken API が登場 | D32: 選べる構成・方法が増え、以前の常識（NLBが必須、トークンはインターネット経由だけ）が変わった | E32: 最新の仕様を前提に、改めて方式を選び直す必要が出た（このガイドの目的）

Sheet 04_構成と経路
B2: 構成と経路（部品ごとの役割・制限・監視点と、各方式が通る範囲）
B3: ■＝通る ■（入口）＝JMeterが最初につなぐ場所 ●＝トークン取得のときだけ通る □＝通らない －＝関係しない
B6: 1. 経路上の部品と、各方式が通る範囲
B7: No | C7: 部品（区間） | D7: 役割 | E7: たとえ | F7: 方式A | G7: 方式B | H7: 方式C | I7: 主な制限・既定値（試験に効くもの） | J7: 主な監視メトリクス
B8: 0 | C8: JMeter（負荷をかける側） | D8: リクエストを作って送り、応答時間・エラーを記録する | E8: ロボット軍団 | F8: ■ | G8: ■ | H8: ■ | I8: 負荷をかける側のCPU・メモリ・ネットワークが先に詰まると、システムを実際より遅く評価してしまう | J8: JMeterホストのCPU使用率・メモリ・GC・ネットワーク量
B9: 1 | C9: Cognito（トークン取得） | D9: client_credentials（/oauth2/token）または GetClientToken でアクセストークンを発行 | E9: チケット売り場 | F9: ● | G9: ● | H9: － | I9: ClientAuthentication は150RPS（アカウント×リージョンで共有・引き上げ不可）。アクセストークンの有効期限は5分〜1日（既定60分）。1件ごとに課金 | J9: Service Quotas の使用状況（ClientAuthentication）、トークン取得の応答コード
B10: 2 | C10: 利用側インターフェイスVPCエンドポイント（PrivateLink） | D10: 利用側のVPCから、エンドポイントサービスへ入る入口 | E10: トンネルの入口 | F10: ■（入口） | G10: □ | H10: □ | I10: 帯域は既定でAZあたり10Gbps（自動で最大100Gbps）。MTUは8500バイト。エンドポイントのSG・ポリシー・名前解決が関係する | J10: AWS/PrivateLinkEndpoints：ActiveConnections、NewConnections、BytesProcessed、PacketsDropped
B11: 3 | C11: VPCエンドポイントサービス（NLB） | D11: PrivateLinkで公開された入口。L4で execute-api VPCエンドポイントのIPへ振り分ける | E11: 交通整理係 | F11: ■ | G11: ■（入口） | H11: □ | I11: TCPアイドルタイムアウトは既定350秒（60〜6000秒で変更可、TLSリスナーは350秒固定）。クロスゾーン負荷分散は既定でオフ。SGはNLBの作成時にしか付けられない | J11: AWS/NetworkELB：ActiveFlowCount、NewFlowCount、ProcessedBytes、TCP_Client／ELB／Target_Reset_Count、UnHealthyHostCount、SecurityGroupBlockedFlowCount_Inbound
B12: 4 | C12: execute-api インターフェイスVPCエンドポイント | D12: プライベートAPIへの入口（API Gateway用のエンドポイント） | E12: 受付の建物のドア | F12: ■ | G12: ■ | H12: □ | I12: APIのリソースポリシーで許可されたVPCエンドポイントからしか呼べない。帯域は2と同じ | J12: AWS/PrivateLinkEndpoints（2と同じ）
B13: 5 | C13: API Gateway（プライベートREST API） | D13: 認可、流量制限、変換、統合先へのルーティング | E13: 正門の受付・改札 | F13: ■ | G13: ■ | H13: □ | I13: アカウント×リージョンで10,000RPS（バースト5,000）をすべてのAPIで共有。統合タイムアウトは既定29秒（Regional・プライベートは引き上げ可、その場合アカウントの流量上限が下がることがある）。ペイロードの上限は10MB | J13: AWS/ApiGateway：Count、Latency、IntegrationLatency、4XXError、5XXError（アクセスログ・X-Rayも）
B14: 6 | C14: Cognitoオーソライザー | D14: トークンの署名・有効期限・スコープを確認する | E14: リストバンド読み取り機 | F14: ■ | G14: ■ | H14: □ | I14: メソッドにOAuthスコープが無いとIDトークン扱いになり、アクセストークンは401。トークン検証（aud）の正規表現を設定すると、アクセストークンは拒否される | J14: 4XXError（401）、アクセスログの $context.authorizer.claims.client_id
B15: 7 | C15: VPCリンク v2 | D15: API Gateway から VPC 内の内部ALBへのプライベートな通路 | E15: 関係者通路 | F15: ■ | G15: ■ | H15: □ | I15: 作成後にサブネット・SGは変えられない。60日間通信が無いとINACTIVEになり、再開に数分かかる。関係する資源が同じアカウントにあることが条件 | J15: 直接のメトリクスは少ない。API Gateway の IntegrationLatency と ALB 側のメトリクスで間接的に見る
B16: 8 | C16: 内部ALB | D16: HTTPの中身（Host・パス）を見て、ECSのタスクへ振り分ける | E16: 案内係 | F16: ■ | G16: ■ | H16: ■（入口） | I16: アイドルタイムアウトは既定60秒。5分以内に2倍を超える急増にはLCU予約を検討。リスナールール（Host・パス・ヘッダー）やJWT検証の設定に注意 | J16: AWS/ApplicationELB：RequestCount、TargetResponseTime、HTTPCode_ELB_5XX_Count、HTTPCode_Target_5XX_Count、RejectedConnectionCount、ActiveConnectionCount、ConsumedLCUs、PeakLCUs
B17: 9 | C17: ECSサービス（タスク内コンテナ） | D17: アプリの処理を実行する。Auto Scaling でタスク数を増減する | E17: 店員さん | F17: ■ | G17: ■ | H17: ■ | I17: スケールアウトの反応と起動に数分かかる。最大タスク数、CPU・メモリの割り当て、ヘルスチェックに注意 | J17: CPUUtilization、MemoryUtilization、RunningTaskCount（Container Insights）、アプリのログ
B18: 10 | C18: RDS Proxy | D18: DB接続をプールして使い回す。接続の殺到からDBを守る | E18: 倉庫前の整理係 | F18: ■ | G18: ■ | H18: ■ | I18: MaxConnectionsPercent、接続の借用タイムアウト、セッションのピン留め（固定）で接続が使い回せなくなることに注意 | J18: ClientConnections、DatabaseConnections、DatabaseConnectionsCurrentlySessionPinned、DatabaseConnectionsBorrowLatency、QueryDatabaseResponseLatency
B19: 11 | C19: Aurora Serverless v2（MySQL） | D19: データの保存と検索。負荷に応じて容量（ACU）を自動で調整する | E19: 魔法の倉庫 | F19: ■ | G19: ■ | H19: ■ | I19: 最小〜最大ACUの範囲でしか増えない。増えるのに時間がかかる。RDS Proxy が接続を保つため、自動一時停止（0 ACU）は起きない | J19: ServerlessDatabaseCapacity、ACUUtilization、CPUUtilization、DatabaseConnections、DMLLatency・SelectLatency・CommitLatency、Deadlocks
C20: 通る部品の数（■と●の数。12部品中） | F20: =COUNTIF(F8:F19,"■*")+COUNTIF(F8:F19,"●") -> 12 | G20: =COUNTIF(G8:G19,"■*")+COUNTIF(G8:G19,"●") -> 11 | H20: =COUNTIF(H8:H19,"■*")+COUNTIF(H8:H19,"●") -> 5 | I20: 方式Aはすべて、方式Bは利用側PrivateLink区間以外、方式CはALBから先だけを通る
B22: 2. 各方式の経路（ひと目でわかる版）
C23: 方式 | D23: 経路（▶の順に通る）
C24: 方式A（フル経路） | D24: JMeter ▶ 利用側VPCエンドポイント ▶ NLB（エンドポイントサービス） ▶ execute-api VPCエンドポイント ▶ API Gateway（Cognitoオーソライザーで認可） ▶ VPCリンク v2 ▶ 内部ALB ▶ ECS ▶ RDS Proxy ▶ Aurora
C25: 方式B（NLB入口） | D25: JMeter ▶ NLB（エンドポイントサービス） ▶ execute-api VPCエンドポイント ▶ API Gateway（Cognitoオーソライザーで認可） ▶ VPCリンク v2 ▶ 内部ALB ▶ ECS ▶ RDS Proxy ▶ Aurora
C26: 方式C（ALB直結） | D26: JMeter ▶ 内部ALB ▶ ECS ▶ RDS Proxy ▶ Aurora
C27: トークン（方式A・B） | D27: JMeter ▶（NATゲートウェイ等の外向き通信） ▶ Cognito（/oauth2/token または GetClientToken） ※最初の1回と、期限前の更新のときだけ
B29: 3. 各方式の入口（JMeterの置き場所と接続先）
C30: 方式 | D30: JMeterの置き場所 | F30: 接続先（名前解決） | J30: 送る主なヘッダー・パス
C31: 方式A（フル経路） | D31: 利用側VPC（または JMeter専用の利用側VPC）のプライベートサブネット。Cognitoへ出るための NATゲートウェイ等 | F31: 本番と同じFQDN（利用側VPCエンドポイントに名前解決される） | J31: Authorization: Bearer <アクセストークン>（APIキーが必須なら x-api-key も）
C32: 方式B（NLB入口） | D32: 提供側VPC（NLBと同じVPC）、またはNLBへルーティングできるネットワーク。NATゲートウェイ等 | F32: 本番と同じFQDNを、JMeterの DNS Cache Manager（静的ホスト）でNLBへ向ける | J32: 方式Aと同じ
C33: 方式C（ALB直結） | D33: 内部ALBに届くVPC（同じVPCを推奨）のプライベートサブネット。NATは不要 | F33: API Gateway の統合URIのホスト名（静的ホストでALBへ向ける）、またはALBのDNS名 | J33: Host（統合URIのホスト名）と、API Gateway が付けているヘッダー。パスはステージ名を含む形（例：/prod/orders）

Sheet 05_方式比較
B2: 方式比較（メリット・デメリットを観点ごとに）
B3: 詳しいメリット・デメリットと対策は 07〜09 の各シート、重み付き評価は 06 を見てください
B6: 1. 観点ごとの比較
B7: 観点 | C7: 方式A（フル経路） | D7: 方式B（NLB入口） | E7: 方式C（ALB直結）
B8: ひとことで | C8: 正門から入る：本番の利用者と同じ道・同じ手順 | D8: トンネルの出口から入る：提供側の入口から先を本番どおりに | E8: 裏口から入る：受付を通らずにアプリとDBへ
B9: JMeterの入口 | C9: 利用側インターフェイスVPCエンドポイント（本番と同じFQDN） | D9: VPCエンドポイントサービスの本体であるNLB | E9: 内部ALB
B10: 通る部品（04シート） | C10: すべて（12部品中12） | D10: 利用側PrivateLink区間以外（12部品中11） | E10: ALBから先だけ（12部品中5）
B11: Cognitoのトークン | C11: 必要（最初に1回取得して共有し、期限前に更新） | D11: 必要（方式Aと同じ） | E11: 原則不要（ALBのJWT検証やアプリでのJWT検証をしている場合は必要）
B12: JMeterの置き場所 | C12: 利用側VPC（または専用の利用側VPC）＋Cognitoへの外向き通信 | D12: 提供側VPCなどNLBに届く場所＋Cognitoへの外向き通信 | E12: ALBに届くVPC（外向き通信は不要）
B13: 主な設定変更 | C13: Cognitoに専用アプリクライアントを追加（専用の利用側VPCを作るなら、エンドポイントサービスの許可と承認も） | D13: 方式Aの内容＋NLB（またはターゲット）のSGでJMeterを許可 | E13: ALBのSGでJMeterを期限付きで許可＋Host・パス・ヘッダーの再現
B14: 測れること | C14: 利用者が体験する応答時間・エラー・制限のすべて | D14: 提供側（API Gateway 以降）のすべて | E14: バックエンド（アプリ・RDS Proxy・DB）の実力と限界
B15: 測れないこと | C15: ほぼ無し（区間ごとの内訳はメトリクスで分解する） | D15: 利用側PrivateLink区間（利用側エンドポイント・名前解決・AZの対応） | E15: API Gateway・認可・スロットリング・29秒タイムアウト・NLB・PrivateLink
B16: 向いている目的 | C16: 受入判定（合否）、SLA確認、耐久試験、スパイク試験 | D16: PrivateLink区間の切り分け、利用側の環境を用意できないときの代替 | E16: ボトルネック調査、チューニング、バックエンドの限界性能の把握
B17: セキュリティへの影響 | C17: 低：正規の認可経路だけを使う | D17: 低〜中：正規の認可経路だが、提供側の入口（NLB）に許可を追加する | E17: 中〜高：認可を通らない経路を一時的に作る（最小限の許可・期限付き・撤去が必須）
B18: 試験の費用 | C18: 高め：API Gateway、PrivateLink 2区間、NLB、ALB、少量のトークン | D18: 中：方式Aから利用側PrivateLink区間の分が減る | E18: 低：ALBから先だけ
... B20: 総合評価 | C20: ◎ 受入判定の主軸 | D20: ○〜△ 補助（必要なときだけ） | E20: ◎ 事前調査の主軸／× 受入判定には使えない
B22: 2. 設定変更・確認の項目数（10_設定変更一覧から自動で数えます）
B23: 区分 | C23: 方式A | D23: 方式B | E23: 方式C
B24: ◎ 必須 | C24: =COUNTIF('10_設定変更一覧'!G8:G91,"◎") -> 39 | D24: =COUNTIF('10_設定変更一覧'!H8:H91,"◎") -> 41 | E24: =COUNTIF('10_設定変更一覧'!I8:I91,"◎") -> 27
B25: ○ 推奨 | C25: =COUNTIF('10_設定変更一覧'!G8:G91,"○") -> 17 | D25: =COUNTIF('10_設定変更一覧'!H8:H91,"○") -> 16 | E25: =COUNTIF('10_設定変更一覧'!I8:I91,"○") -> 12
B26: △ 条件付き | C26: =COUNTIF('10_設定変更一覧'!G8:G91,"△") -> 17 | D26: =COUNTIF('10_設定変更一覧'!H8:H91,"△") -> 14 | E26: =COUNTIF('10_設定変更一覧'!I8:I91,"△") -> 8
B27: 合計（◎＋○＋△） | C27: =SUM(C24:C26) -> 73 | D27: =SUM(D24:D26) -> 71 | E27: =SUM(E24:E26) -> 47
B28: 参考：さらに内側（ECSタスクのIPへ直接、DBへ直接JDBC）から負荷をかける方法もありますが、ALBの振り分け・ヘルスチェック・接続の分散を通らないため、通常は方式Cで十分です。
B29: 項目数が多い＝悪い、ではありません。方式Aの項目の多くは「確認」で、試験対象（API定義）そのものは変えません。方式Cは項目が少なめでも、認可を通らない経路を作る（5-1）という重い変更を含みます。

Sheet 06_評価マトリクス
B2: 評価マトリクス（重み付き評価）
B3: 目的（受入判定／ボトルネック調査）ごとに重みを変えて、3方式を100点満点で比べます。網掛けセルは編集できます。
B5: 点数（1〜5）は本ガイドによる評価です。5がいちばん良い。網掛けの重み・点数を自分の組織の事情に合わせて変えると、総合点と順位が自動で再計算されます。重みの合計は、目的ごとに100にしてください。
B7: 1. 評価表（網掛けセルの重み・点数は編集できます）
B8: No | C8: 評価観点 | D8: 何を評価するか | E8: 重み 受入判定 | F8: 重み ボトルネック調査 | G8: 方式A | H8: 方式B | I8: 方式C | J8: 採点の理由（方式A） | K8: 採点の理由（方式B） | L8: 採点の理由（方式C）
B9: 1 | C9: 本番再現性（経路・認可・制限の忠実度） | D9: 利用者と同じ部品・設定・制限を通るか。測った値をそのまま「本番の性能」と言えるか | E9: 30 | F9: 10 | G9: 5 | H9: 4 | I9: 1 | J9: すべての部品を、本番と同じ順番・同じ認可で通る | K9: 利用側PrivateLink区間（利用側エンドポイント・名前解決・AZの対応）だけ通らない | L9: API Gateway・認可・スロットリング・NLB・PrivateLinkを通らない
B10: 2 | C10: ボトルネックの切り分けやすさ | D10: 遅いとき・エラーのときに、原因の部品を特定しやすいか | E10: 10 | F10: 30 | G10: 2 | H10: 3 | I10: 5 | J10: 12の部品が直列で、内訳はメトリクスで分解する必要がある | K10: 利用側区間を外せるので、方式Aとの差で切り分けに使える | L10: 部品が少なく、アプリ・DBの問題に集中できる
B11: 3 | C11: JMeterシナリオの作りやすさ・保守性 | D11: スクリプトの複雑さ、壊れやすさ | E11: 10 | F11: 15 | G11: 2 | H11: 2 | I11: 4 | J11: トークンの取得・共有・更新のロジックが必要 | K11: 方式Aと同じトークン処理に加え、FQDNをNLBへ向ける静的ホストの設定が必要 | L11: トークンは不要。ただし Host・パス・ヘッダーの再現が必要
B12: 4 | C12: 実行環境（ネットワーク）の用意しやすさ | D12: JMeterを置ける場所と、通信経路の準備の手間 | E12: 10 | F12: 10 | G12: 2 | H12: 3 | I12: 4 | J12: 利用側VPC（または専用の利用側VPC＋エンドポイントの承認）と、Cognitoへの外向き通信が必要 | K12: 提供側VPCと、Cognitoへの外向き通信が必要 | L12: ALBに届くVPCだけでよい（外向き通信は不要）
B13: 5 | C13: 試験対象（SUT）への変更の少なさ | D13: 試験のために、本番と同じ設定を変える量とその影響 | E13: 10 | F13: 5 | G13: 4 | H13: 3 | I13: 3 | J13: Cognitoにアプリクライアントを1つ追加する程度（専用の利用側VPCを使う場合はエンドポイントサービスの許可を追加） | K13: 方式Aに加えて、NLB（またはターゲット）のSGの変更が必要 | L13: ALBのSGの変更が必要（ヘッダー条件を使っている場合は追加の調整も）
B14: 6 | C14: セキュリティリスクの低さ | D14: 試験のための変更が、認可を迂回する経路や消し忘れのリスクを生まないか | E14: 15 | F14: 10 | G14: 5 | H14: 4 | I14: 2 | J14: 正規の認可経路だけを使う | K14: 正規の認可経路を使うが、提供側の入口（NLB）への許可を追加する | L14: 認可を通らない経路を一時的に作る（期限付き・最小限の許可・撤去が必須）
B15: 7 | C15: 試験コストの低さ | D15: 試験そのものにかかる AWS の料金 | E15: 5 | F15: 10 | G15: 2 | H15: 3 | I15: 5 | J15: API Gateway のリクエスト料金、PrivateLink 2区間のデータ処理料金、NLB・ALBの利用料、少量のトークン料金 | K15: 方式Aから、利用側PrivateLink区間の料金が減る | L15: API Gateway・PrivateLink・NLB の料金がかからない
B16: 8 | C16: 外部クォータ・他システムへの影響の小ささ | D16: アカウントで共有する上限（API Gateway 10,000RPS、Cognito 150RPS）や、他システムへの波及 | E16: 10 | F16: 10 | G16: 3 | H16: 3 | I16: 5 | J16: API Gateway のアカウント上限を消費する（トークンは少量なので Cognito への影響は小さい） | K16: 方式Aと同じ | L16: API Gateway・Cognito の上限を消費しない
C17: 重みの合計（それぞれ100にする） | D17: =IF(AND(E17=100,F17=100),"OK（合計が100）","重みの合計を100にしてください") -> OK（合計が100） | E17: =SUM(E9:E16) -> 100 | F17: =SUM(F9:F16) -> 100 | J17: 点数は1〜5（5がいちばん良い）。重みは0〜100。
B19: 2. 結果（自動計算）
C20: 項目 | E20: 目的 | G20: 方式A | H20: 方式B | I20: 方式C | J20: 読み方
C21: 総合点（100点満点） | E21: 受入判定 | G21: =SUMPRODUCT($E$9:$E$16,G$9:G$16)/(5*SUM($E$9:$E$16))*100 -> 73 | H21: =SUMPRODUCT($E$9:$E$16,H$9:H$16)/(5*SUM($E$9:$E$16))*100 -> 67 | I21: =SUMPRODUCT($E$9:$E$16,I$9:I$16)/(5*SUM($E$9:$E$16))*100 -> 59 | J21: 数字が大きいほど、その目的に向いている
C22: 順位 | E22: 受入判定 | G22: =RANK(G21,$G$21:$I$21) -> 1 | H22: =RANK(H21,$G$21:$I$21) -> 2 | I22: =RANK(I21,$G$21:$I$21) -> 3 | J22: 1がいちばん向いている
C23: 足切り条件（本番再現性が4以上） | E23: 受入判定 | G23: =IF(G9>=4,"適格","不適格") -> 適格 | H23: =IF(H9>=4,"適格","不適格") -> 適格 | I23: =IF(I9>=4,"適格","不適格") -> 不適格 | J23: 本番と違う経路で測った値は、合否の根拠にならないため
C24: 総合点（100点満点） | E24: ボトルネック調査 | G24: =SUMPRODUCT($F$9:$F$16,G$9:G$16)/(5*SUM($F$9:$F$16))*100 -> 56 | H24: =SUMPRODUCT($F$9:$F$16,H$9:H$16)/(5*SUM($F$9:$F$16))*100 -> 61 | I24: =SUMPRODUCT($F$9:$F$16,I$9:I$16)/(5*SUM($F$9:$F$16))*100 -> 79 | J24: 数字が大きいほど、その目的に向いている
C25: 順位 | E25: ボトルネック調査 | G25: =RANK(G24,$G$24:$I$24) -> 3 | H25: =RANK(H24,$G$24:$I$24) -> 2 | I25: =RANK(I24,$G$24:$I$24) -> 1 | J25: 1がいちばん向いている
B27: 3. 注意点
B28: 1 | C28: 総合点＝Σ（重み×点数）÷（5×重みの合計）×100。100点満点に換算しています。
B29: 2 | C29: 受入判定には「足切り条件」を設けています：本番再現性が4未満の方式は、総合点に関係なく受入判定に使えません（本番と違う経路で測った値は、合否の根拠にならないため）。
B30: 3 | C30: 重みを変えると順位が入れかわることがあります（例：受入判定で本番再現性の重みを下げ、切り分けやすさの重みを上げると方式Cの点が上がる）。だからこそ、受入判定では足切り条件で本番再現性を担保しています。

Sheet 07_方式A_フル経路
B2: 方式A：フル経路（Cognitoのトークン取得から全経路を通す）
B3: メリット・デメリット、JMeter用に変える設定、シナリオのポイント、結果の読み方、疎通確認、後片付け
B6: 1. 概要
B7: ひとことで | C7: 本番の利用者と同じ道を、同じ手順（トークン取得 → API呼び出し）で通す方式です。
B8: 経路（トークン） | C8: JMeter →（NATゲートウェイ等の外向き通信）→ Cognito のトークンエンドポイント（/oauth2/token）または GetClientToken API ※最初の1回と、期限前の更新のときだけ
B9: 経路（API） | C9: JMeter → 利用側インターフェイスVPCエンドポイント（PrivateLink） → VPCエンドポイントサービス（NLB） → execute-api インターフェイスVPCエンドポイント → API Gateway（プライベートREST API＋Cognitoオーソライザー） → VPCリンク v2 → 内部ALB → ECSサービス（タスク内コンテナ） → RDS Proxy → Aurora Serverless v2（MySQL）
B10: この方式で答えが出る問い | C10: (1) 利用者から見て、ピーク時の応答時間・エラー率は目標どおりか（合否） (2) どの部品の、どの上限に最初にぶつかるか (3) トークンの更新をまたぐ長時間でも安定しているか (4) スパイク（急増）のとき、スケールが間に合うか
B11: 前提条件 | C11: (1) JMeterを利用側VPC（本番の利用者と同じ側）に置ける。利用側VPCが他部署・他社のものなら、JMeter専用の「利用側VPC」を作り、エンドポイントサービス宛てのインターフェイスVPCエンドポイントを作る（許可プリンシパルの追加・接続の承認・AZ IDの一致） (2) JMeterから Cognito のトークンエンドポイントへ外向きのHTTPS（NAT／プロキシ） (3) JMeter専用アプリクライアント（本番と同じスコープ） (4) 本番と同じFQDNで名前解決できる
B13: 2. メリット
B14: メリット | C14: 重要度 | D14: 内容 | E14: 根拠
B15: 合否判定にそのまま使える | C15: ◎ | D15: 利用者と同じ部品・設定・制限（API Gateway のスロットリング、29秒タイムアウト、10MBの上限、認可）を通るため、測った値を「本番の性能」として説明できる。 | E15: 04_構成と経路：12部品中12部品を通る
B16: 部品どうしの「つなぎ目」の問題を見つけられる | C16: ◎ | D16: タイムアウトの連鎖（API Gateway 29秒、ALB 60秒、NLB 350秒、アプリ・DB）、keep-alive とアイドルタイムアウトの不一致、SNI／Host、ヘッダーの大きさなど、部品単体では出ない問題が出る。 | E16: 各部品の既定値が違うため（04_構成と経路の「主な制限」）
B17: 認可（JWT検証）にかかる時間も含めて測れる | C17: ○ | D17: Cognitoオーソライザーの検証時間も、API Gateway の Latency に含まれる。 | E17: API Gateway の Latency と IntegrationLatency の差で確認できる
B18: 試験対象への変更が最小 | C18: ○ | D18: Cognitoにアプリクライアントを1つ足すだけ。API定義やオーソライザーには触らない。 | E18: 10_設定変更一覧（API Gateway の項目は確認のみ）
B19: スケールの連鎖を本番どおりの順番で確かめられる | C19: ○ | D19: 前段の流量制御を通った後の負荷がバックエンドに届くため、ALB → ECS → RDS Proxy → Aurora に本番と同じ形の負荷がかかる。 | E19: 前段（API Gateway）での制限・平準化が含まれるため
B20: 長時間の試験で、トークン更新の動きも確かめられる | C20: ○ | D20: 本番クライアントの更新のタイミングで、問題が出ないかを確かめられる。 | E20: 更新用スレッドグループで再現できる（11_JMeter設計）
B22: 3. デメリットと対策
B23: デメリット | C23: 重要度 | D23: 内容 | E23: 対策
B24: JMeterの置き場所の条件が厳しい | C24: ◎ | D24: Cognitoへの外向き通信と、プライベートな入口への到達の両方が必要。 | E24: プライベートサブネット＋NATゲートウェイで実行する（外からの受信の公開は不要）。閉域が必須なら、外部で取得したトークンを渡すか、GetClientToken＋cognito-idp のVPCエンドポイント（ドメインの無いユーザープールのみ）を使う。
B25: トークン処理でスクリプトが複雑になる | C25: ○ | D25: 取得・共有・更新・失敗時の停止が必要。 | E25: 11_JMeter設計のひな形（setUp＋更新スレッド＋props共有）をそのまま使う。
B26: 原因の切り分けに手間がかかる | C26: ○ | D26: 直列の部品が多い。 | E26: API Gateway の Latency／IntegrationLatency、ALB の TargetResponseTime、RDS Proxy の待ち時間などで区間ごとに分解する（13_監視と判定）。事前に方式Cでバックエンドの実力をつかんでおく。
B27: 試験の費用がいちばん高い | C27: ○ | D27: API Gateway のリクエスト料金、PrivateLink（2区間）のデータ処理料金、NLB・ALB の利用料がかかる。 | E27: 短い試験を段階的に行い、試験時間を計画的に使う（12_負荷とトークン試算で概算）。
B28: アカウントで共有する上限に当たる | C28: ◎ | D28: API Gateway は1アカウント・1リージョンで10,000RPS（バースト5,000）をすべてのAPIで共有している。 | E28: 試験専用のアカウントを使う。目標が上限を超えるなら事前に申請する。
B29: 利用側の環境の調整が必要な場合がある | C29: △ | D29: 利用側VPCが他社・他部署のもので、JMeterを置けない。 | E29: JMeter専用の利用側VPCを作り、エンドポイントサービスの許可プリンシパルの追加と接続の承認を、提供側に依頼する。
B31: 4. この方式でJMeter用に変更・追加・確認する設定（10_設定変更一覧から抜粋：73項目）
B32: ◎＝必須 ○＝推奨 △＝条件付き（該当する場合のみ）。ほかの方式との比較は「10_設定変更一覧」で見られます。
B33: 分類 | C33: 要否 | D33: 対象と、変更・確認の内容 | E33: 理由／元に戻す方法／確認方法
B34: 共通準備 | C34: ◎ | D34: 【0-1】試験環境 本番と分けた、本番と同じ作りの環境（できれば別のAWSアカウント）で行う。本番との差分を一覧にする | E34: 理由：API Gateway（10,000RPS）や Cognito（150RPS）の上限はアカウント×リージョン単位で共有され、同じアカウントの他システムを巻き込むため 戻し方：－ 確認：差分一覧
B35: 共通準備 | C35: ◎ | D35: 【0-2】関係者への周知・承認 試験の日時・負荷量・送信元・連絡先を、運用監視・セキュリティ・利用側VPCの所有者・他システムの担当へ伝え、承認を得る | E35: 理由：アラームへの誤対応や、他システムへの影響を防ぐため 戻し方：－ 確認：承認の記録
B36: 共通準備 | C36: ◎ | D36: 【0-3】AWSのテストポリシー Amazon EC2 テストポリシーを確認する（正当なリクエストによる負荷試験は可能。意図的なフラッディングはDDoSの扱いで禁止） | E36: 理由：規約違反やトラフィックの制限を避けるため 戻し方：－ 確認：確認日とURLを記録
B37: 共通準備 | C37: ◎ | D37: 【0-4】目標値と合否基準 目標RPS・試験時間・p95／p99の応答時間・エラー率を数値で決める | E37: 理由：合否判定と、どこまで負荷をかけるかの基準になるため 戻し方：－ 確認：13_監視と判定の合否表
B38: 共通準備 | C38: ◎ | D38: 【0-5】スケールに関わる設定 ECSの Auto Scaling（最小・最大タスク数、ポリシー）、Auroraの最小・最大ACU、RDS Proxy の設定を本番と同じにする | E38: 理由：違うと、結果が本番の性能を表さないため 戻し方：－ 確認：設定値の比較
B39: 共通準備 | C39: ◎ | D39: 【0-6】テストデータ 本番相当の件数・分布のデータを用意し、試験の前にDBのスナップショットを取る | E39: 理由：DBの性能はデータの量と分布で大きく変わるため。更新系のAPIではデータが変わるため 戻し方：スナップショットから復元 確認：件数の確認
B40: 共通準備 | C40: △ | D40: 【0-7】API Gateway のアカウント上限 目標RPSが10,000RPS（バースト5,000）を超えるなら、Service Quotas で事前に引き上げを申請する | E40: 理由：上限を超えると429になり、試験にならないため（承認に時間がかかることがある） 戻し方：通常は戻す必要なし 確認：Service Quotas の値
B41: 共通準備 | C41: △ | D41: 【0-8】LCU予約（ALB／NLB） 5分以内に2倍を超えて増えるスパイク試験をするなら、LCU予約を検討する（本番でも予約するかどうかとそろえる） | E41: 理由：自動スケールが追いつかず、503や接続拒否が出るのを防ぐため 戻し方：予約を解除 確認：PeakLCUs、予約の状態
B42: Cognito | C42: ◎ | D42: 【1-1】JMeter専用アプリクライアント 既存のユーザープールに、クライアントシークレットありのアプリクライアントを新しく作る（例：loadtest-jmeter-202611） | E42: 理由：本番クライアントの資格情報を使い回さないため（漏えい・失効の影響を分け、ログでJMeterの通信を見分けられる） 戻し方：試験後に削除 確認：aws cognito-idp describe-user-pool-client
B43: Cognito | C43: ◎ | D43: 【1-2】許可するフロー（トークンエンドポイント方式） AllowedOAuthFlows に client_credentials を設定し、AllowedOAuthFlowsUserPoolClient を true にする（/oauth2/token を使う場合。1-3とどちらか一方） | E43: 理由：本番クライアントと同じ取り方で試験するため 戻し方：クライアントの削除で消える 確認：トークン取得の成功
B44: Cognito | C44: △ | D44: 【1-3】許可するフロー（GetClientToken方式・2026年8月〜） ExplicitAuthFlows に ALLOW_CLIENT_TOKEN_AUTH だけを設定する（ほかの認証フローとは併用できない） | E44: 理由：ドメインなしで SDK／API 経由でトークンを取れる。VPCエンドポイント（PrivateLink）経由で使えるのは、ユーザープールにドメインが無い場合だけ 戻し方：クライアントの削除で消える 確認：aws cognito-idp get-client-token
... B106: 後片付け | C106: ◎ | D106: 【10-5】JMeterホストと結果 JMeterホストを停止・削除し、結果ファイルの保管場所と保存期間を決める（秘密が含まれていないか確認する） | E106: 理由：不要な費用と情報漏えいを防ぐため 戻し方：－ 確認：－
B108: 5. JMeterシナリオのポイント
...

Sheet 08_方式B_NLB入口
B2: 方式B：NLB入口（VPCエンドポイントサービスのNLBから入れる）
B3: メリット・デメリット、JMeter用に変える設定、シナリオのポイント、結果の読み方、疎通確認、後片付け
B6: 1. 概要
B7: ひとことで | C7: トンネルの出口（提供側のNLB）から入り、受付（API Gateway）から先を本番どおりに通す方式です。
B8: 経路（トークン） | C8: JMeter →（NATゲートウェイ等の外向き通信）→ Cognito のトークンエンドポイント（/oauth2/token）または GetClientToken API ※最初の1回と、期限前の更新のときだけ
B9: 経路（API） | C9: JMeter（提供側VPCの中など） → VPCエンドポイントサービス（NLB） → execute-api インターフェイスVPCエンドポイント → API Gateway（Cognitoオーソライザー） → VPCリンク v2 → 内部ALB → ECSサービス → RDS Proxy → Aurora Serverless v2
B10: この方式で答えが出る問い | C10: (1) 提供側（API Gateway 以降）だけで、目標の性能を満たすか (2) 方式Aとの差から、利用側PrivateLink区間（利用側エンドポイント・名前解決・AZの対応）の影響はどれくらいか (3) 利用側の環境が用意できる前に、提供側を先に確かめられるか
B11: 前提条件 | C11: (1) JMeterを提供側VPC（または NLB へルーティングできるネットワーク）に置ける (2) Cognitoへの外向き通信（方式Aと同じ） (3) NLBのSG（またはターゲット側のSG）でJMeterを許可する (4) 本番と同じFQDNのまま、NLBへ向ける名前解決（JMeterの DNS Cache Manager の静的ホスト）
B13: 2. メリット
B14: メリット | C14: 重要度 | D14: 内容 | E14: 根拠
B15: API Gateway 以降は本番と同じ | C15: ○ | D15: 認可・スロットリング・VPCリンク・ALB・ECS・DBを、本番どおりに確かめられる。 | E15: 04_構成と経路：12部品中11部品を通る
B16: 利用側の環境がいらない | C16: ○ | D16: 提供側のアカウント・VPCだけで準備できる。 | E16: 利用側エンドポイントの作成・承認が不要
B17: PrivateLink利用側区間の切り分けに使える | C17: ○ | D17: 方式Aとの差を見ると、利用側エンドポイント・名前解決・AZの対応の影響がわかる。 | E17: 違うのは利用側PrivateLink区間だけなので
B18: 方式Aより費用が少し安い | C18: △ | D18: 利用側PrivateLink区間のデータ処理料金がかからない。 | E18: 通る区間が1つ少ない
B20: 3. デメリットと対策
B21: デメリット | C21: 重要度 | D21: 内容 | E21: 対策
B22: Cognitoは結局必要 | C22: ◎ | D22: 認可は API Gateway で行うため、トークンの取得・共有・更新の手間は方式Aと同じ。 | E22: 方式Aと同じひな形（11_JMeter設計）を使う。
B23: 本番の入口（利用側PrivateLink区間）を通らない | C23: ◎ | D23: 利用側エンドポイントのSG・ポリシー・名前解決・AZの対応の問題は見つからない。 | E23: 合否判定は方式Aで行う。
B24: 名前（SNI／Host）を本番と同じにする工夫が必要 | C24: ◎ | D24: NLBのDNS名で接続してHostヘッダーだけ書き換えると、SNIとHostがずれる。拡張セキュリティポリシーのSTRICTモードでは拒否される。 | E24: 本番FQDNのまま、DNS Cache Manager の静的ホストでNLBへ向ける（値にNLBのDNS名を入れると、全AZのIPに解決される）。
B25: 気づかないうちにNLBを通っていないことがある | C25: ○ | D25: 提供側VPCで execute-api のプライベートDNSが有効だと、{api-id}.execute-api.<region>.amazonaws.com は execute-api VPCエンドポイントを直接指す。 | E25: 静的ホストでNLBを指定し、NLBの NewFlowCount が増えることを確かめる。
B26: 提供側の入口への許可が必要 | C26: ○ | D26: NLBにSGがあれば、JMeterのSGを許可する。NLBにSGが無く、クライアントIP保持が有効なら、ターゲット（execute-api VPCエンドポイント）のSGで許可する。 | E26: 期限付き・最小限の許可にし、試験後に削除する。
B27: AZの偏りが起きやすい | C27: △ | D27: NLBのクロスゾーン負荷分散は既定でオフ。JMeterが一部のIPに偏ると、一部のAZだけ詰まる。 | E27: DNS Cache Manager で反復ごとにクリアし、AZ別のメトリクスを確認する。
B29: 4. この方式でJMeter用に変更・追加・確認する設定（10_設定変更一覧から抜粋：71項目）
B30: ◎＝必須 ○＝推奨 △＝条件付き（該当する場合のみ）。ほかの方式との比較は「10_設定変更一覧」で見られます。
B31: 分類 | C31: 要否 | D31: 対象と、変更・確認の内容 | E31: 理由／元に戻す方法／確認方法
B32: 共通準備 | C32: ◎ | D32: 【0-1】試験環境 本番と分けた、本番と同じ作りの環境（できれば別のAWSアカウント）で行う。本番との差分を一覧にする | E32: 理由：API Gateway（10,000RPS）や Cognito（150RPS）の上限はアカウント×リージョン単位で共有され、同じアカウントの他システムを巻き込むため 戻し方：－ 確認：差分一覧
B33: 共通準備 | C33: ◎ | D33: 【0-2】関係者への周知・承認 試験の日時・負荷量・送信元・連絡先を、運用監視・セキュリティ・利用側VPCの所有者・他システムの担当へ伝え、承認を得る | E33: 理由：アラームへの誤対応や、他システムへの影響を防ぐため 戻し方：－ 確認：承認の記録
B34: 共通準備 | C34: ◎ | D34: 【0-3】AWSのテストポリシー Amazon EC2 テストポリシーを確認する（正当なリクエストによる負荷試験は可能。意図的なフラッディングはDDoSの扱いで禁止） | E34: 理由：規約違反やトラフィックの制限を避けるため 戻し方：－ 確認：確認日とURLを記録
B35: 共通準備 | C35: ◎ | D35: 【0-4】目標値と合否基準 目標RPS・試験時間・p95／p99の応答時間・エラー率を数値で決める | E35: 理由：合否判定と、どこまで負荷をかけるかの基準になるため 戻し方：－ 確認：13_監視と判定の合否表
B36: 共通準備 | C36: ◎ | D36: 【0-5】スケールに関わる設定 ECSの Auto Scaling（最小・最大タスク数、ポリシー）、Auroraの最小・最大ACU、RDS Proxy の設定を本番と同じにする | E36: 理由：違うと、結果が本番の性能を表さないため 戻し方：－ 確認：設定値の比較
B37: 共通準備 | C37: ◎ | D37: 【0-6】テストデータ 本番相当の件数・分布のデータを用意し、試験の前にDBのスナップショットを取る | E37: 理由：DBの性能はデータの量と分布で大きく変わるため。更新系のAPIではデータが変わるため 戻し方：スナップショットから復元 確認：件数の確認
B38: 共通準備 | C38: △ | D38: 【0-7】API Gateway のアカウント上限 目標RPSが10,000RPS（バースト5,000）を超えるなら、Service Quotas で事前に引き上げを申請する | E38: 理由：上限を超えると429になり、試験にならないため（承認に時間がかかることがある） 戻し方：通常は戻す必要なし 確認：Service Quotas の値
B39: 共通準備 | C39: △ | D39: 【0-8】LCU予約（ALB／NLB） 5分以内に2倍を超えて増えるスパイク試験をするなら、LCU予約を検討する（本番でも予約するかどうかとそろえる） | E39: 理由：自動スケールが追いつかず、503や接続拒否が出るのを防ぐため 戻し方：予約を解除 確認：PeakLCUs、予約の状態
B40: Cognito | C40: ◎ | D40: 【1-1】JMeter専用アプリクライアント 既存のユーザープールに、クライアントシークレットありのアプリクライアントを新しく作る（例：loadtest-jmeter-202611） | E40: 理由：本番クライアントの資格情報を使い回さないため（漏えい・失効の影響を分け、ログでJMeterの通信を見分けられる） 戻し方：試験後に削除 確認：aws cognito-idp describe-user-pool-client
B41: Cognito | C41: ◎ | D41: 【1-2】許可するフロー（トークンエンドポイント方式） AllowedOAuthFlows に client_credentials を設定し、AllowedOAuthFlowsUserPoolClient を true にする（/oauth2/token を使う場合。1-3とどちらか一方） | E41: 理由：本番クライアントと同じ取り方で試験するため 戻し方：クライアントの削除で消える 確認：トークン取得の成功
B42: Cognito | C42: △ | D42: 【1-3】許可するフロー（GetClientToken方式・2026年8月〜） ExplicitAuthFlows に ALLOW_CLIENT_TOKEN_AUTH だけを設定する（ほかの認証フローとは併用できない） | E42: 理由：ドメインなしで SDK／API 経由でトークンを取れる。VPCエンドポイント（PrivateLink）経由で使えるのは、ユーザープールにドメインが無い場合だけ 戻し方：クライアントの削除で消える 確認：aws cognito-idp get-client-token
... B102: 後片付け | C102: ◎ | D102: 【10-5】JMeterホストと結果 JMeterホストを停止・削除し、結果ファイルの保管場所と保存期間を決める（秘密が含まれていないか確認する） | E102: 理由：不要な費用と情報漏えいを防ぐため 戻し方：－ 確認：－
B104: 5. JMeterシナリオのポイント
B105: 1 | C105: トークン処理は方式Aと同じ（setUp＋更新＋props共有）。
B106: 2 | C106: DNS Cache Manager：「カスタムDNSリゾルバーを使用」をONにし、DNSサーバーにVPCのDNS（VPCのCIDRの先頭+2、または169.254.169.253）を指定する。静的ホストに「本番FQDN → NLBのDNS名」を登録し、各反復でキャッシュをクリアする。
...

Sheet 09_方式C_ALB直結
B2: 方式C：ALB直結（内部ALBに直接入れる）
B3: メリット・デメリット、JMeter用に変える設定、シナリオのポイント、結果の読み方、疎通確認、後片付け
B6: 1. 概要
B7: ひとことで | C7: 受付（API Gateway）を通らず、裏口から案内係（内部ALB）へ直接入る方式です。
B8: 経路 | C8: JMeter（ALBに届くVPCの中） → 内部ALB → ECSサービス（タスク内コンテナ） → RDS Proxy → Aurora Serverless v2（Cognito・API Gateway・VPCリンク・NLB・PrivateLink は通らない）
B9: この方式で答えが出る問い | C9: (1) アプリとDBだけの実力（最大スループット、最初に詰まる部品） (2) ECS の Auto Scaling、RDS Proxy、Aurora の容量の設定は妥当か（チューニングの前後比較） (3) 前段（API Gateway）の上限を超える負荷を、バックエンドが受けられるか（将来の拡張の検討）
B10: 前提条件 | C10: (1) JMeterをALBに届くVPC（同じVPCを推奨）に置ける (2) ALBのSGに、JMeterのSGを期限付きで許可する (3) API Gateway がALBに送る Host・パス（ステージ名を含む）・ヘッダーを把握している (4) ALBでJWT検証をしていない（しているならトークンを用意する）
B12: 2. メリット
B13: メリット | C13: 重要度 | D13: 内容 | E13: 根拠
B14: ボトルネックを見つけやすい | C14: ◎ | D14: 部品が少ないので、アプリ・SQL・接続プール・DBの容量の問題に集中できる。 | E14: 04_構成と経路：通るのは12部品中5部品
B15: Cognito・トークンがいらない | C15: ◎ | D15: スクリプトが簡単で、Cognitoへの外向き通信もいらない。 | E15: 認可は API Gateway で行っているため（ALBのJWT検証がない場合）
B16: 前段の上限に縛られない | C16: ○ | D16: API Gateway のスロットリングやアカウントの上限を気にせず、バックエンドの限界まで負荷をかけられる（ストレス試験）。 | E16: API Gateway を通らないため
B17: 費用が安い | C17: ○ | D17: API Gateway・PrivateLink・NLB の料金がかからない。 | E17: 通る部品が少ない
B18: 他システムへの影響が小さい | C18: ○ | D18: API Gateway・Cognito のアカウント共有の上限を消費しない。 | E18: どちらも通らないため
B20: 3. デメリットと対策
B21: デメリット | C21: 重要度 | D21: 内容 | E21: 対策
B22: 合否判定には使えない | C22: ◎ | D22: API Gateway・認可・スロットリング・29秒タイムアウト・PrivateLink・NLB を通らない。 | E22: 合否は方式Aで判定する。方式Cは事前調査と位置づける。
B23: 認可を通らない「裏口」を一時的に作る | C23: ◎ | D23: ALBのSGを開けると、トークンなしでバックエンドに届く。 | E23: 送信元はJMeterのSGだけ（CIDRやVPC全体は不可）。説明欄に期限と目的を書く。試験後すぐ削除し、届かないことを確認する。VPCフローログで他からの接続が無いかも確かめる。
B24: API Gateway が付けるもの（Host・パス・ヘッダー）を再現しないと、別の動きになる | C24: ◎ | D24: プライベート統合では、バックエンドへのパスにステージ名が入る（例：/prod/orders）。Host は統合URIのホスト名。認可クレームを渡すマッピングや共有シークレットのヘッダーがあれば、それも必要。 | E24: 統合の設定（aws apigateway get-integration）と ALB のアクセスログで、API Gateway 経由のリクエストを確認して同じにする。
B25: 負荷の形が本番と違う | C25: ○ | D25: 本番では API Gateway のスロットリングで頭打ちになる負荷が、そのままバックエンドに届く。接続元も VPCリンクのENI ではなく JMeter になる。 | E25: 結果は「バックエンドの上限」として読む。
B26: タイムアウトの判定が違う | C26: ○ | D26: ALBのアイドルタイムアウトは既定60秒なので、本番なら504になる30秒を超える処理も成功に見える。 | E26: JMeterの応答タイムアウトを29秒にして、本番の504相当を失敗として数える。
B27: ALBでJWT検証やヘッダー条件を使っていると、手間が増える | C27: △ | D27: ALBのリスナーでJWT検証（2025年11月〜）を有効にしていると、トークンが必要になる。 | E27: 条件に合わせたトークン・ヘッダーを用意する。
B29: 4. この方式でJMeter用に変更・追加・確認する設定（10_設定変更一覧から抜粋：47項目）
B30: ◎＝必須 ○＝推奨 △＝条件付き（該当する場合のみ）。ほかの方式との比較は「10_設定変更一覧」で見られます。
B31: 分類 | C31: 要否 | D31: 対象と、変更・確認の内容 | E31: 理由／元に戻す方法／確認方法
B32: 共通準備 | C32: ◎ | D32: 【0-1】試験環境 本番と分けた、本番と同じ作りの環境（できれば別のAWSアカウント）で行う。本番との差分を一覧にする | E32: 理由：API Gateway（10,000RPS）や Cognito（150RPS）の上限はアカウント×リージョン単位で共有され、同じアカウントの他システムを巻き込むため 戻し方：－ 確認：差分一覧
B33: 共通準備 | C33: ◎ | D33: 【0-2】関係者への周知・承認 試験の日時・負荷量・送信元・連絡先を、運用監視・セキュリティ・利用側VPCの所有者・他システムの担当へ伝え、承認を得る | E33: 理由：アラームへの誤対応や、他システムへの影響を防ぐため 戻し方：－ 確認：承認の記録
B34: 共通準備 | C34: ◎ | D34: 【0-3】AWSのテストポリシー Amazon EC2 テストポリシーを確認する（正当なリクエストによる負荷試験は可能。意図的なフラッディングはDDoSの扱いで禁止） | E34: 理由：規約違反やトラフィックの制限を避けるため 戻し方：－ 確認：確認日とURLを記録
B35: 共通準備 | C35: ◎ | D35: 【0-4】目標値と合否基準 目標RPS・試験時間・p95／p99の応答時間・エラー率を数値で決める | E35: 理由：合否判定と、どこまで負荷をかけるかの基準になるため 戻し方：－ 確認：13_監視と判定の合否表
B36: 共通準備 | C36: ◎ | D36: 【0-5】スケールに関わる設定 ECSの Auto Scaling（最小・最大タスク数、ポリシー）、Auroraの最小・最大ACU、RDS Proxy の設定を本番と同じにする | E36: 理由：違うと、結果が本番の性能を表さないため 戻し方：－ 確認：設定値の比較
B37: 共通準備 | C37: ◎ | D37: 【0-6】テストデータ 本番相当の件数・分布のデータを用意し、試験の前にDBのスナップショットを取る | E37: 理由：DBの性能はデータの量と分布で大きく変わるため。更新系のAPIではデータが変わるため 戻し方：スナップショットから復元 確認：件数の確認
B38: 共通準備 | C38: △ | D38: 【0-8】LCU予約（ALB／NLB） 5分以内に2倍を超えて増えるスパイク試験をするなら、LCU予約を検討する（本番でも予約するかどうかとそろえる） | E38: 理由：自動スケールが追いつかず、503や接続拒否が出るのを防ぐため 戻し方：予約を解除 確認：PeakLCUs、予約の状態
B39: Cognito | C39: △ | D39: 【1-9】client_id を使うアプリの処理 アプリが client_id（トークンのクレーム）で利用者やテナントを見分けているなら、JMeter用の client_id をアプリ側の許可リスト・設定に登録する | E39: 理由：未登録だと403やデータなしになり、本番と違う処理を測ってしまうため 戻し方：登録を削除 確認：アプリのログ
B40: ネットワーク | C40: ◎ | D40: 【2-1】JMeterの実行基盤 VPC内のプライベートサブネットに EC2（または ECS／Fargate）でJMeterを置く。パブリックIPは付けない | E40: 理由：プライベートAPIや内部ALBには、VPCの中（またはつながったネットワーク）からしか届かないため 戻し方：インスタンス・タスクの削除 確認：curlでの疎通
B41: ネットワーク | C41: ◎ | D41: 【2-4】置き場所（方式C） 内部ALBに届くVPC（同じVPCを推奨）に置く | E41: 理由：内部ALBはVPCの外からは届かないため 戻し方：インスタンスの削除 確認：ALBへの接続
B42: ネットワーク | C42: △ | D42: 【2-7】プロキシの除外設定 JMeterを -H／-P でプロキシ経由にする場合は、-N（プロキシを使わないホスト）にプライベートAPIのFQDNとALBのFQDNを入れる | E42: 理由：API呼び出しまでプロキシを通ると経路が変わり、プロキシが先に詰まるため 戻し方：－ 確認：プロキシのログにAPI呼び出しが無いこと
... B78: 後片付け | C78: ◎ | D78: 【10-5】JMeterホストと結果 JMeterホストを停止・削除し、結果ファイルの保管場所と保存期間を決める（秘密が含まれていないか確認する） | E78: 理由：不要な費用と情報漏えいを防ぐため 戻し方：－ 確認：－
B80: 5. JMeterシナリオのポイント
B81: 1 | C81: setUp（トークン取得）は不要（ALBのJWT検証や、アプリでのJWT検証がある場合は、方式Aと同じトークン処理を入れる）。
B82: 2 | C82: HTTP Header Manager で Host（統合URIのホスト名）と、API Gateway が付けているヘッダーを付ける。
...

Sheet 10_設定変更一覧
B2: JMeter用に変更・追加・確認すべき設定の一覧（完全版）
B3: ◎＝必須 ○＝推奨 △＝条件付き（該当する場合のみ） －＝不要。見出し行のフィルターで方式（A・B・C）ごとに絞り込めます。「状態」は「未／済／対象外」から選べます。
B6: 設定変更・確認の一覧（全84項目）
B7: No | C7: 分類 | D7: 対象（設定の場所） | E7: 変更・確認の内容 | F7: なぜ必要か | G7: A | H7: B | I7: C | J7: 元に戻す方法 | K7: 確認方法 | L7: 状態
B8: 0-1 | C8: 共通準備 | D8: 試験環境 | E8: 本番と分けた、本番と同じ作りの環境（できれば別のAWSアカウント）で行う。本番との差分を一覧にする | F8: API Gateway（10,000RPS）や Cognito（150RPS）の上限はアカウント×リージョン単位で共有され、同じアカウントの他システムを巻き込むため | G8: ◎ | H8: ◎ | I8: ◎ | J8: － | K8: 差分一覧 | L8: 未
B9: 0-2 | C9: 共通準備 | D9: 関係者への周知・承認 | E9: 試験の日時・負荷量・送信元・連絡先を、運用監視・セキュリティ・利用側VPCの所有者・他システムの担当へ伝え、承認を得る | F9: アラームへの誤対応や、他システムへの影響を防ぐため | G9: ◎ | H9: ◎ | I9: ◎ | J9: － | K9: 承認の記録 | L9: 未
B10: 0-3 | C10: 共通準備 | D10: AWSのテストポリシー | E10: Amazon EC2 テストポリシーを確認する（正当なリクエストによる負荷試験は可能。意図的なフラッディングはDDoSの扱いで禁止） | F10: 規約違反やトラフィックの制限を避けるため | G10: ◎ | H10: ◎ | I10: ◎ | J10: － | K10: 確認日とURLを記録 | L10: 未
B11: 0-4 | C11: 共通準備 | D11: 目標値と合否基準 | E11: 目標RPS・試験時間・p95／p99の応答時間・エラー率を数値で決める | F11: 合否判定と、どこまで負荷をかけるかの基準になるため | G11: ◎ | H11: ◎ | I11: ◎ | J11: － | K11: 13_監視と判定の合否表 | L11: 未
B12: 0-5 | C12: 共通準備 | D12: スケールに関わる設定 | E12: ECSの Auto Scaling（最小・最大タスク数、ポリシー）、Auroraの最小・最大ACU、RDS Proxy の設定を本番と同じにする | F12: 違うと、結果が本番の性能を表さないため | G12: ◎ | H12: ◎ | I12: ◎ | J12: － | K12: 設定値の比較 | L12: 未
B13: 0-6 | C13: 共通準備 | D13: テストデータ | E13: 本番相当の件数・分布のデータを用意し、試験の前にDBのスナップショットを取る | F13: DBの性能はデータの量と分布で大きく変わるため。更新系のAPIではデータが変わるため | G13: ◎ | H13: ◎ | I13: ◎ | J13: スナップショットから復元 | K13: 件数の確認 | L13: 未
B14: 0-7 | C14: 共通準備 | D14: API Gateway のアカウント上限 | E14: 目標RPSが10,000RPS（バースト5,000）を超えるなら、Service Quotas で事前に引き上げを申請する | F14: 上限を超えると429になり、試験にならないため（承認に時間がかかることがある） | G14: △ | H14: △ | I14: － | J14: 通常は戻す必要なし | K14: Service Quotas の値 | L14: 未
B15: 0-8 | C15: 共通準備 | D15: LCU予約（ALB／NLB） | E15: 5分以内に2倍を超えて増えるスパイク試験をするなら、LCU予約を検討する（本番でも予約するかどうかとそろえる） | F15: 自動スケールが追いつかず、503や接続拒否が出るのを防ぐため | G15: △ | H15: △ | I15: △ | J15: 予約を解除 | K15: PeakLCUs、予約の状態 | L15: 未
B16: 1-1 | C16: Cognito | D16: JMeter専用アプリクライアント | E16: 既存のユーザープールに、クライアントシークレットありのアプリクライアントを新しく作る（例：loadtest-jmeter-202611） | F16: 本番クライアントの資格情報を使い回さないため（漏えい・失効の影響を分け、ログでJMeterの通信を見分けられる） | G16: ◎ | H16: ◎ | I16: － | J16: 試験後に削除 | K16: aws cognito-idp describe-user-pool-client | L16: 未
B17: 1-2 | C17: Cognito | D17: 許可するフロー（トークンエンドポイント方式） | E17: AllowedOAuthFlows に client_credentials を設定し、AllowedOAuthFlowsUserPoolClient を true にする（/oauth2/token を使う場合。1-3とどちらか一方） | F17: 本番クライアントと同じ取り方で試験するため | G17: ◎ | H17: ◎ | I17: － | J17: クライアントの削除で消える | K17: トークン取得の成功 | L17: 未
B18: 1-3 | C18: Cognito | D18: 許可するフロー（GetClientToken方式・2026年8月〜） | E18: ExplicitAuthFlows に ALLOW_CLIENT_TOKEN_AUTH だけを設定する（ほかの認証フローとは併用できない） | F18: ドメインなしで SDK／API 経由でトークンを取れる。VPCエンドポイント（PrivateLink）経由で使えるのは、ユーザープールにドメインが無い場合だけ | G18: △ | H18: △ | I18: － | J18: クライアントの削除で消える | K18: aws cognito-idp get-client-token | L18: 未
... B91: 10-5 | C91: 後片付け | D91: JMeterホストと結果 | E91: JMeterホストを停止・削除し、結果ファイルの保管場所と保存期間を決める（秘密が含まれていないか確認する） | F91: 不要な費用と情報漏えいを防ぐため | G91: ◎ | H91: ◎ | I91: ◎ | J91: － | K91: － | L91: 未
B92: 同じ分類の行は同じ背景色にしています（分類ごとに白と薄い灰色を交互）。方式ごとの抜粋は 07〜09 の各シートの「4.」にもあります。

Sheet 11_JMeter設計
B2: JMeterの設計（テストプランの構成・設定・スクリプト例）
B3: JMeter 5.6.3／Java 17以上を前提にしています。<…> は自分の環境の値に置き換えてください
B6: 1. テストプランの構成（方式A・Bの例。方式Cは setUp と更新用を外し、Host などのヘッダーを足す）
B7: No | C7: 要素（ツリー） | E7: 役割・ポイント
B8: 1 | C8: テストプラン | E8: 全体。接続先などは ${__P(名前,既定値)} の形にして、-J オプションで切り替えられるようにする
B9: 2 | C9: ├ ユーザー定義変数 | E9: HOST、BASE_PATH、TOKEN_URL、SCOPE など（秘密は入れない）
B10: 3 | C10: ├ DNS Cache Manager | E10: 各反復でクリア。方式B・Cは静的ホストでつなぐ先を指定
B11: 4 | C11: ├ HTTP Request Defaults | E11: https／本番と同じFQDN／443／HttpClient4／タイムアウト
B12: 5 | C12: ├ setUp Thread Group（1スレッド×1回） | E12: 最初に1回だけトークンを取得する（方式A・B）
B13: 6 | C13: │ └ HTTP Request「[SETUP] Cognito Token」 | E13: POST /oauth2/token（または GetClientToken）
B14: 7 | C14: │ ├ HTTP Header Manager | E14: Content-Type と Authorization: Basic …
B15: 8 | C15: │ ├ JSR223 PostProcessor | E15: トークンと有効期限を props に保存（トークンはログに出さない）
B16: 9 | C16: │ └ Result Status Action Handler | E16: 失敗したら試験を止める（JSR223 の後ろに置く）
B17: 10 | C17: ├ Thread Group「[REFRESH] Token Refresher」（1スレッド） | E17: 試験が有効期限より長いときだけ。期間は試験時間と同じにする
B18: 11 | C18: │ ├ If Controller（期限の5分前を過ぎた？） | E18: ${__groovy(…)} で判定する
B19: 12 | C19: │ │ └ HTTP Request「[SETUP] Cognito Token Refresh」 | E19: 取り直して props を上書き（子要素はトークン取得と同じ）
... B28: 21 | C28: └ （デバッグのときだけ）View Results Tree | E28: CLIで実行するときは無効にする
B30: 2. 主な要素の設定
B31: No | C31: 要素 | D31: 設定項目 | E31: 推奨値 | F31: 理由 | G31: 対象の方式
B32: 1 | C32: ユーザー定義変数 | D32: 接続先・パス・スコープなど（秘密以外） | E32: HOST、BASE_PATH、TOKEN_URL、SCOPE など。値は ${__P(HOST,既定値)} の形にする | F32: 環境（試験環境・方式）の切り替えを、JMXを書き換えずに -J で行うため | G32: A／B／C
B33: 2 | C33: HTTP Request Defaults | D33: プロトコル／サーバー名／ポート | E33: https ／ 本番と同じFQDN（方式Cは統合URIのホスト名） ／ 443 | F33: SNIとHostを本番と同じにするため（STRICTモード対策） | G33: A／B／C
B34: 3 | C34: HTTP Request Defaults | D34: 実装（Implementation） | E34: HttpClient4 | F34: DNS Cache Manager が働くのは HttpClient4 だけのため | G34: A／B／C
B35: 4 | C35: HTTP Request Defaults | D35: 接続タイムアウト／応答タイムアウト | E35: 例：5,000ms ／ 35,000ms（方式Cは29,000ms） | F35: 異常時に早く失敗させ、API Gateway の29秒（504）を正しく受け取るため。方式Cでは本番の504相当を失敗として数えるため | G35: A／B／C
B36: 5 | C36: HTTP Request（各API） | D36: Use KeepAlive | E36: ON（既定） | F36: 本番のM2Mクライアントと同じく、接続を使い回すため | G36: A／B／C
B37: 6 | C37: DNS Cache Manager | D37: 各反復でキャッシュをクリア | E37: ON | F37: JVMのDNSキャッシュで、特定のIP（AZ・ノード）に偏るのを防ぐため | G37: A／B／C
B38: 7 | C38: DNS Cache Manager | D38: DNSリゾルバー | E38: 静的ホストを使うときは「カスタムDNSリゾルバー」をONにし、VPCのDNS（VPCのCIDRの先頭+2、または169.254.169.253）を指定 | F38: VPCの中の名前（プライベートDNS）を正しく引くため | G38: B（A・Cは必要なとき）
B39: 8 | C39: DNS Cache Manager | D39: 静的ホスト（Static Host Table） | E39: 方式B：本番FQDN → NLBのDNS名。方式C：統合URIのホスト名 → ALBのDNS名（カンマ区切りで複数のIPも指定可） | F39: 名前（SNI／Host）は本番と同じにしたまま、つなぐ先だけを変えるため | G39: B／C
B40: 9 | C40: setUp Thread Group | D40: スレッド数／ループ回数 | E40: 1／1 | F40: 最初に1回だけトークンを取得するため | G40: A／B
B41: 10 | C41: トークン取得の HTTP Request | D41: ラベル | E41: [SETUP] Cognito Token | F41: HTMLレポートから除外するための目印 | G41: A／B
B42: 11 | C42: トークン取得の HTTP Request | D42: メソッド／パス／本文 | E42: POST ／ /oauth2/token ／ grant_type=client_credentials と scope=<リソースサーバーID>/<スコープ名> | F42: Cognito のトークンエンドポイントの仕様（client_secret_basic または client_secret_post） | G42: A／B
B43: 12 | C43: トークン取得の HTTP Header Manager | D43: ヘッダー | E43: Content-Type: application/x-www-form-urlencoded と Authorization: Basic <Base64(client_id:client_secret)> | F43: client_secret_basic 方式。Base64 は __groovy 関数で作れる | G43: A／B
... B55: 24 | C55: リスナー | D55: GUIのリスナー | E55: 「結果をツリーで表示」などは無効にする（CLI実行では使わない） | F55: 負荷をかける力が落ちるのと、トークンが画面に出るのを防ぐため | G55: A／B／C
B57: 3. DNS Cache Manager の設定例（方式B・C）
B58: No | C58: 方式 | D58: リゾルバーの設定 | F58: 静的ホスト
B59: 1 | C59: 方式B | D59: カスタムDNSリゾルバーを使用：ON ／ DNSサーバー：10.0.0.2（VPCのCIDRが 10.0.0.0/16 の例） | F59: 静的ホスト：api.example.internal → <NLBのDNS名>
B60: 2 | C60: 方式C | D60: カスタムDNSリゾルバーを使用：ON ／ DNSサーバー：10.0.0.2 | F60: 静的ホスト：backend.example.internal（統合URIのホスト名） → <内部ALBのDNS名>
B62: 4. スクリプト・設定ファイル・コマンドの例
B63: トークン取得のリクエスト（/oauth2/token、client_secret_basic）
B64: POST https://<ドメインプレフィックス>.auth.<region>.amazoncognito.com/oauth2/token
B65: Content-Type: application/x-www-form-urlencoded
...

Sheet 12_負荷とトークン試算
B2: 負荷とトークンの試算
B3: 網掛けセル（D列）に自分の値を入れると、下の結果が自動で計算されます。最初に入っている値は例です
B6: 1. 入力（網掛けセルを書き換える）
B7: No | C7: 項目 | D7: 値 | E7: 単位 | F7: 説明・出典
B8: 1 | C8: 目標スループット | D8: 200 | E8: RPS | F8: ピーク時に1秒あたりに来るリクエスト数（例の値。自分の目標に置き換える）
B9: 2 | C9: 平均応答時間 | D9: 0.3 | E9: 秒 | F9: 1リクエストの平均応答時間の見込み（低負荷の疎通試験の結果などから）
B10: 3 | C10: 余裕係数 | D10: 1.5 | E10: 倍 | F10: 応答が遅くなったときにもRPSを保つための余裕（1.5〜2が目安）
B11: 4 | C11: 試験時間 | D11: 60 | E11: 分 | F11: 定常の計測時間（ウォームアップを含めて考える）
B12: 5 | C12: アクセストークンの有効期限 | D12: 60 | E12: 分 | F12: Cognito の既定は60分（5分〜1日で設定可）
B13: 6 | C13: 期限前に更新する時間 | D13: 5 | E13: 分 | F13: 期限の何分前に取り直すか（本ガイドの推奨は5分）
B14: 7 | C14: 負荷をかける機械の台数 | D14: 2 | E14: 台 | F14: JMeterを動かす台数（分散実行のとき）
B15: 8 | C15: トークン1件あたりの料金 | D15: 0.00225 | E15: USD | F15: Cognito M2M の米国東部（バージニア北部）の例。無料枠なし。リージョンにより異なるので料金ページで確認
B16: 9 | C16: ClientAuthentication の上限 | D16: 150 | E16: RPS | F16: Cognito のクォータ（アカウント×リージョンで共有、引き上げ不可）
B17: 10 | C17: API Gateway REST API の料金 | D17: 3.5 | E17: USD／100万件 | F17: 米国東部の最初の3億3,300万件の例（要確認）。リージョン・量により異なる
B19: 2. 結果（自動計算）
B20: No | C20: 項目 | D20: 値 | E20: 単位 | F20: 計算のしかた・意味
B21: 1 | C21: 必要な同時スレッド数（目安） | D21: =ROUNDUP(ROUND(D8*D9*D10,6),0) -> 90 | E21: スレッド | F21: リトルの法則：同時に処理中の数 ≒ RPS × 応答時間。余裕係数をかけて切り上げ
B22: 2 | C22: 試験中のAPIリクエストの総数 | D22: =D8*D11*60 -> 720000 | E22: 件 | F22: 目標RPS × 試験時間（秒）
B23: 3 | C23: トークン取得の回数（推奨：共有＋期限前の更新） | D23: =IF(D12<=D13,"有効期限を「期限前に更新する時間」より長くしてください",D14*(1+IF(D11<=D12-D13,0,ROUNDDOWN(D11/(D12-D13),0)))) -> 4 | E23: 件 | F23: 台数 ×（最初の1回＋更新の回数）。更新の間隔＝有効期限−期限前の更新時間
B24: 4 | C24: トークン取得の回数（毎リクエストで取得した場合） | D24: =D22 -> 720000 | E24: 件 | F24: 毎リクエストでトークンを取ると、APIのリクエスト数と同じ回数になる
B25: 5 | C25: トークンの料金（推奨のやり方） | D25: =IF(ISNUMBER(D23),D23*D15,"－") -> 0.009 | E25: USD | F25: 推奨のやり方でのトークン料金
B26: 6 | C26: トークンの料金（毎リクエストで取得した場合） | D26: =D24*D15 -> 1620 | E26: USD | F26: 毎リクエストで取った場合のトークン料金（推奨との差を見てください）
B27: 7 | C27: 毎リクエスト取得は、推奨の何倍の料金か | D27: =IF(AND(ISNUMBER(D25),N(D25)>0),D26/D25,"－") -> 180000 | E27: 倍 | F27: 推奨のやり方との料金の比（推奨の料金が0のときは表示しない）
B28: 8 | C28: 毎リクエスト取得のときのトークン取得レート | D28: =D8 -> 200 | E28: RPS | F28: 毎リクエストで取ると、トークン取得のレートは目標RPSと同じになる
B29: 9 | C29: 上限（ClientAuthentication）との比較 | D29: =IF(D28>D16,"上限（"&TEXT(D16,"#,##0")&"RPS）を超える：トークン取得が拒否され、試験ができない","上限内。ただし同じアカウント・リージョンの他システムと上限を取り合う") -> 上限（150RPS）を超える：トークン取得が拒否され、試験ができない | F29: 上限を超えると TooManyRequestsException で取得できず、試験そのものができない
B30: 10 | C30: API Gateway のリクエスト料金（概算） | D30: =D22/1000000*D17 -> 2.52 | E30: USD | F30: API Gateway のリクエスト料金の概算（PrivateLink・NLB・ALBなどの料金は別）
B31: 11 | C31: 1スレッドあたりの目標RPS | D31: =IF(N(D21)>0,D8/D21,0) -> 2.2222222 | E31: RPS／スレッド | F31: 1スレッドが受け持つRPS（Precise Throughput Timer の設定の参考）
B33: 3. 読み方
B34: 1 | C34: 毎リクエストでトークンを取ると、トークン取得のレート＝目標RPSになります。上限（150RPS）を超えると取得が拒否され、試験そのものができません。超えなくても、同じアカウント・リージョンの他システムと上限を取り合います。
B35: 2 | C35: 推奨のやり方（最初に1回＋期限前の更新）なら、トークンの取得は試験全体で数回だけで、料金もほとんどかかりません。
B36: 3 | C36: 必要なスレッド数は目安です。疎通試験で測った応答時間で計算し直し、実際のRPSが目標に届いているかを結果で確かめてください。
B37: 4 | C37: API Gateway のほかにも、PrivateLink（時間料金・データ処理料金）、NLB・ALB（LCU）、ECS・Aurora などの料金がかかります。正確な見積もりは AWS Pricing Calculator で行ってください。

Sheet 13_監視と判定
B2: 監視と判定（何を見て、どう判断するか）
B3: 部品ごとのメトリクス、遅延の分解、合否判定表
B6: 1. 見るべきメトリクス（部品ごと）
B7: No | C7: 部品 | D7: メトリクス | E7: 取得元 | H7: 見る理由 | I7: 目安・判断
B8: 1 | C8: JMeter | D8: 応答時間（平均・p90・p95・p99）、スループット（RPS）、エラー率、接続時間（Connect）、最初の1バイトまでの時間（Latency） | E8: JMeterの結果（JTL／HTMLレポート） | H8: 利用者から見た性能。合否判定の主な材料 | I8: p95・p99を目標と比べる。エラーの内訳（401／403／429／5xx）
B9: 2 | C9: JMeterホスト | D9: CPU使用率、メモリ、GC、ネットワークの送受信量 | E9: CloudWatch（EC2）、OSのツール | H9: 負荷をかける側が詰まっていないか | I9: CPUが70〜80%を超えたら台数を増やす
B10: 3 | C10: Cognito | D10: トークン取得の回数、TooManyRequestsException、応答コード | E10: Service Quotas（ClientAuthentication の使用状況）、JMeterの [SETUP] サンプラー | H10: トークン取得が上限に近づいていないか | I10: 取得の回数は「台数×（1＋更新の回数）」程度に収まるはず
B11: 4 | C11: PrivateLink（利用側VPCE・execute-api VPCE） | D11: ActiveConnections、NewConnections、BytesProcessed、PacketsDropped | E11: AWS/PrivateLinkEndpoints | H11: トンネル区間の詰まり・取りこぼし | I11: PacketsDropped が増えていないか
B12: 5 | C12: NLB | D12: ActiveFlowCount、NewFlowCount、ProcessedBytes、TCP_Client_Reset_Count、TCP_ELB_Reset_Count、TCP_Target_Reset_Count、UnHealthyHostCount、SecurityGroupBlockedFlowCount_Inbound | E12: AWS/NetworkELB | H12: 接続の数・リセット・SGでのブロック | I12: リセットの急増、ブロックの数（許可漏れ）
B13: 6 | C13: API Gateway | D13: Count、Latency、IntegrationLatency、4XXError、5XXError | E13: AWS/ApiGateway（ステージ・メソッド単位）、アクセスログ、X-Ray | H13: API Gateway の中の時間と統合先の時間の切り分け、429・504の発生 | I13: Latency − IntegrationLatency が急に増えていないか
B14: 7 | C14: ALB | D14: RequestCount、TargetResponseTime、HTTPCode_ELB_5XX_Count、HTTPCode_Target_5XX_Count、RejectedConnectionCount、ActiveConnectionCount、NewConnectionCount、ConsumedLCUs、PeakLCUs | E14: AWS/ApplicationELB、ALBのアクセスログ | H14: アプリの応答時間と、ALB自身のエラー（502／503／504） | I14: ELB_5XX はALB側、Target_5XX はアプリ側の問題
B15: 8 | C15: ECS | D15: CPUUtilization、MemoryUtilization、RunningTaskCount、タスクの起動・停止 | E15: AWS/ECS、Container Insights、アプリのログ | H15: アプリの処理能力と、スケールの速さ | I15: CPUが高止まり → タスク数・タスクのサイズ・コードを見直す
B16: 9 | C16: RDS Proxy | D16: ClientConnections、DatabaseConnections、DatabaseConnectionsCurrentlyBorrowed、DatabaseConnectionsCurrentlySessionPinned、DatabaseConnectionsBorrowLatency、QueryDatabaseResponseLatency | E16: AWS/RDS（プロキシ単位） | H16: 接続の取り合い・ピン留め | I16: BorrowLatency が増える → 接続数の上限、ピン留めの原因のSQL
B17: 10 | C17: Aurora Serverless v2 | D17: ServerlessDatabaseCapacity、ACUUtilization、CPUUtilization、DatabaseConnections、SelectLatency、DMLLatency、CommitLatency、Deadlocks | E17: AWS/RDS、Performance Insights／CloudWatch Database Insights、スロークエリログ | H17: DBの容量とSQLの重さ | I17: ACUが最大に張り付く → 最大ACU・SQL・インデックスを見直す
B19: 2. 遅延の分解（どこで時間がかかっているか）
B20: No | C20: 区間 | D20: 計算のしかた | E20: 意味
B21: 1 | C21: 利用者の体験（全体） | D21: JMeterの応答時間（Elapsed） | E21: 方式Aでは、利用者が体験する時間にいちばん近い
B22: 2 | C22: 前段のネットワーク（PrivateLink・NLB・TLS） | D22: JMeterの応答時間 − API Gateway の Latency | E22: トンネル区間とTLS接続にかかる時間の目安
B23: 3 | C23: API Gateway の中（認可を含む） | D23: API Gateway の Latency − IntegrationLatency | E23: オーソライザー・マッピングなどにかかる時間
B24: 4 | C24: VPCリンク＋ALB | D24: API Gateway の IntegrationLatency − ALB の TargetResponseTime | E24: 通路と案内係にかかる時間
B25: 5 | C25: アプリ（ECS） | D25: ALB の TargetResponseTime（＝方式Cで測れる範囲の大部分） | E25: アプリの処理とDB待ちを含む
B26: 6 | C26: DB待ち | D26: RDS Proxy の QueryDatabaseResponseLatency・DatabaseConnectionsBorrowLatency、Aurora の各Latency | E26: アプリの時間のうち、DBに使った時間
B27: 差を取るときは、同じ時間帯・同じ統計（平均どうし、p95どうし）で比べてください。パーセンタイルどうしの引き算は厳密ではなく、目安です。方式Aと方式Cの結果の差も、同じ考え方で「前段が足している時間」の目安になります。
B29: 3. 合否判定表（網掛けセルに目標値と実測値を入れると、判定が自動で出ます）
B30: No | C30: 指標 | D30: 測り方 | E30: 条件 | F30: 目標値 | G30: 実測値 | H30: 判定 | I30: 備考
B31: 1 | C31: p95 応答時間（ミリ秒） | D31: JMeter の HTMLレポート（95th pct）。ウォームアップを除いた定常区間 | E31: 以下 | F31: 500 | G31: 420 | H31: =IF(OR(F31="",G31=""),"",IF(E31="以下",IF(G31<=F31,"合格","不合格"),IF(G31>=F31,"合格","不合格"))) -> 合格 | I31: 例の値。合否の基準は事前に関係者と合意する
B32: 2 | C32: p99 応答時間（ミリ秒） | D32: JMeter の HTMLレポート（99th pct） | E32: 以下 | F32: 1000 | G32: 1150 | H32: =IF(OR(F32="",G32=""),"",IF(E32="以下",IF(G32<=F32,"合格","不合格"),IF(G32>=F32,"合格","不合格"))) -> 不合格 | I32: 例の値
B33: 3 | C33: エラー率 | D33: JMeter の HTMLレポート（Error %）。[SETUP] は除外 | E33: 以下 | F33: 0.001 | G33: 0.0004 | H33: =IF(OR(F33="",G33=""),"",IF(E33="以下",IF(G33<=F33,"合格","不合格"),IF(G33>=F33,"合格","不合格"))) -> 合格 | I33: 401／403／429／5xx をすべて含む
B34: 4 | C34: スループット（RPS） | D34: JMeter の HTMLレポート（Throughput） | E34: 以上 | F34: 200 | G34: 205 | H34: =IF(OR(F34="",G34=""),"",IF(E34="以下",IF(G34<=F34,"合格","不合格"),IF(G34>=F34,"合格","不合格"))) -> 合格 | I34: 目標どおりの負荷がかかっていたか
B35: 5 | C35: 429（スロットリング）の件数 | D35: JMeter の応答コード別件数、API Gateway のアクセスログ | E35: 以下 | F35: 0 | G35: 0 | H35: =IF(OR(F35="",G35=""),"",IF(E35="以下",IF(G35<=F35,"合格","不合格"),IF(G35>=F35,"合格","不合格"))) -> 合格 | I35: 本番の制限込みの試験なら、想定どおりかで判断
B36: 6 | C36: 5xx の件数 | D36: JMeter の応答コード別件数、API Gateway の 5XXError、ALB の 5XX | E36: 以下 | F36: 0 | G36: 3 | H36: =IF(OR(F36="",G36=""),"",IF(E36="以下",IF(G36<=F36,"合格","不合格"),IF(G36>=F36,"合格","不合格"))) -> 不合格 | I36: どこで出たか（API Gateway／ALB／アプリ）を確認
B37: 7 | C37: JMeterホストのCPU使用率（最大） | D37: CloudWatch（EC2）の CPUUtilization の最大値 | E37: 以下 | F37: 0.8 | G37: 0.62 | H37: =IF(OR(F37="",G37=""),"",IF(E37="以下",IF(G37<=F37,"合格","不合格"),IF(G37>=F37,"合格","不合格"))) -> 合格 | I37: 超えていたら、結果は参考値として扱う
C38: 総合判定（1つでも不合格なら不合格） | H38: =IF(COUNTIF(H31:H37,"不合格")>0,"不合格",IF(COUNTIF(H31:H37,"合格")=0,"","合格")) -> 不合格
B39: 最初に入っている値は記入例です（p99 と 5xx の件数が不合格になる例）。実際の目標値と実測値で上書きしてください。エラー率とCPU使用率は小数（0.1% → 0.001、80% → 0.8）で入力します。

Sheet 14_誤解と落とし穴
B2: 誤解と落とし穴（よくある勘違いと、症状から探す原因と対策）
B6: 1. よくある誤解と事実
B7: No | C7: よくある誤解 | D7: 事実（正しくは） | E7: 根拠
B8: 1 | C8: Cognitoでトークンを取るには、パブリックにアクセスできる端末が必要 | D8: 必要なのは「外向き」のHTTPS通信だけ。プライベートサブネット＋NATゲートウェイ（またはプロキシ）で実行できる。外から入ってこられる公開端末は不要 | E8: トークンエンドポイントはユーザープールのドメインに付く公開エンドポイントで、PrivateLinkでは届かない（AWS公式）
B9: 2 | C9: Cognito が PrivateLink に対応（2025年11月）したので、閉域でトークンが取れる | D9: /oauth2/token（クライアントクレデンシャル）は PrivateLink 非対応。閉域で取れるのは GetClientToken（2026年8月〜）を cognito-idp のVPCエンドポイント経由で呼ぶ場合で、ユーザープールにドメインが無いことが条件 | E9: Cognito 開発者ガイド「Access Amazon Cognito using an interface endpoint」
B10: 3 | C10: JMeter用に Cognito オーソライザーを追加する必要がある | D10: 不要。同じユーザープールのアプリクライアントが発行したトークンは、既存のオーソライザーで検証される。追加・付け替えは本番と同じAPI定義の変更になるので避ける | E10: API Gateway 開発者ガイド（COGNITO_USER_POOLS オーソライザー）
B11: 4 | C11: NLB（エンドポイントサービス）に直接つなげば Cognito はいらない | D11: 認可は API Gateway で行うので、NLBから入ってもトークンは必要 | E11: オーソライザーは API Gateway のメソッドに付いている
B12: 5 | C12: ALB直結の結果で合格と言える | D12: 言えない。API Gateway・認可・スロットリング・29秒タイムアウト・PrivateLink・NLB を通っていない。合否はフル経路（方式A）で判定する | E12: 04_構成と経路（方式Cは12部品中5部品だけを通る）
B13: 6 | C13: 毎回トークンを取得するほうが本番に近い | D13: 本番のM2Mクライアントも、トークンを期限まで使い回すのが作法。毎回取ると Cognito の上限（150RPS）に当たり、1件ごとの料金もかかる | E13: Cognito のクォータ（ClientAuthentication 150RPS・引き上げ不可）、AWS公式の「JWTをキャッシュする」推奨、Cognito の料金
B14: 7 | C14: トークンの有効期限を最大にすれば、更新は考えなくてよい | D14: 最大は1日。長い試験には更新のロジックを入れ、本番と同じ有効期限で試すのが望ましい | E14: Cognito のクォータ（アクセストークン 5分〜1日）
B15: 8 | C15: API Gateway は自動でスケールするので上限はない | D15: アカウント×リージョンで10,000RPS（バースト5,000）が既定で、すべてのAPIで共有。超える場合は事前に引き上げを申請する | E15: API Gateway のクォータ
B16: 9 | C16: JMeterは証明書が合わなければエラーで止まる | D16: JMeterは既定でサーバー証明書を検証しない。名前の不一致に気づきにくいので、事前に curl で本番と同じ名前で接続を確かめる。STRICTモードでは SNI と Host の不一致で拒否される | E16: JMeterの仕様、API Gateway のエンドポイントアクセスモード
B17: 10 | C17: Aurora Serverless v2 は一瞬で大きくなる | D17: 容量は段階的に増える。最小ACUが小さいと立ち上がりが遅い。ウォームアップが必要 | E17: Aurora Serverless v2 の仕組み
B18: 11 | C18: スレッド数＝RPS | D18: RPS ≒ スレッド数 ÷ 応答時間（秒）。目標RPSはスループットの制御（Precise Throughput Timer など）で作る | E18: リトルの法則（12_負荷とトークン試算）
B19: 12 | C19: Open Model Thread Group を使えば、いつでも本番どおり | D19: 到着ごとに新しいスレッドを作るため、接続の使い回しが起きにくい。接続を使い回すM2Mクライアントを再現するなら、固定スレッド＋スループット制御が向く | E19: JMeter のソースコード（OpenModelThreadGroup）
B21: 2. 症状から探す落とし穴
B22: No | C22: 症状 | D22: 主な原因 | E22: 対策
B23: 1 | C23: 401 Unauthorized | D23: メソッドにOAuthスコープが無い（IDトークン扱い）、スコープの不一致、トークン検証（aud）の正規表現が設定されている、期限切れ、「Bearer 」の付け忘れ | E23: メソッドのスコープとトークンの scope を確認する。更新ロジックを入れる。ヘッダーの形を確認する
B24: 2 | C24: 403 Forbidden（プライベートAPI） | D24: リソースポリシーで許可されていないVPCエンドポイントから来ている、Host・SNIが合わない、APIキーが無い、WAFでブロック | E24: 本番と同じFQDNで接続する。リソースポリシーとVPCエンドポイントのIDを確認する。x-api-key、WAFのログを確認する
B25: 3 | C25: 429 Too Many Requests | D25: API Gateway のスロットリング（ステージ・メソッド・使用量プラン・アカウントの上限）、Cognito のトークン取得の上限 | E25: 設定値と目標RPSを比べる。トークンは共有して使い回す
B26: 4 | C26: 502／503（ALB） | D26: ターゲット不足（ECSのスケールの遅れ）、ヘルスチェックの失敗、LCU不足 | E26: 最小タスク数・スケールの設定、ウォームアップ、LCU予約
